Workbook

Sheet 商管公司1月实际
A1: ____商管公司__2026年 1月度核算表（实际）
A2: 项目 | B2: 序号 | C2: 科目 | D2: 计算公式 | E2: 1月实际 | F2: 年度预算 当月目标 | G2: 月度预定 | H2: 销售额 占比 | I2: 月度实绩 | J2: 销售额 占比 | K2: 预（定）实 （绩）差异额 | L2: （实绩达成） 预定比 | M2: （实绩达成） 年度预算比 | N2: 2月预定/1月实际
A3: 收入 | B3: A1 | C3: 民俗邨项目 | D3: 从软件直接取数或统计明细 | F3: 448156 | G3: 448156 | I3: 462886.05 | J3: =I3/$I$6 -> 0.020896167 | K3: =I3-G3 -> 14730.05 | L3: =I3/G3 -> 1.0328681 | M3: =I3/F3 -> 1.0328681 | N3: =F3/E3 -> #DIV/0!
B4: A2 | C4: 时光城项目 | D4: 从软件直接取数或统计明细 | F4: 538396.76 | G4: 538396.76 | I4: 552400 | J4: =I4/$I$6 -> 0.024937115 | K4: =I4-G4 -> 14003.24 | L4: =I4/G4 -> 1.0260091 | M4: =I4/F4 -> 1.0260091 | N4: =F4/E4 -> #DIV/0!
B5: A3 | C5: 威高广场项目 | D5: 从软件直接取数或统计明细 | F5: 20174817 | G5: 20184917 | I5: 21136435 | J5: =I5/$I$6 -> 0.95416672 | K5: =I5-G5 -> 951517.54 | L5: =I5/G5 -> 1.04714 | M5: =I5/F5 -> 1.0476643 | N5: =F5/E5 -> #DIV/0!
B6: A | C6: 总销售额 | D6: A=A1+A2+A3+A4 | F6: =SUM(F3:F5) -> 21161370 | G6: =SUM(G3:G5) -> 21171470 | I6: =SUM(I3:I5) -> 22151721 | K6: =I6-G6 -> 980250.83 | L6: =I6/G6 -> 1.0463006 | M6: =I6/F6 -> 1.0467999 | N6: =F6/E6 -> #DIV/0!
A7: 费用 | B7: B1 | C7: 民俗邨项目 | D7: 从软件直接取数或统计明细 | F7: 125700 | G7: 125700 | I7: 126500 | J7: =I7/$I$6 -> 0.0057106173 | K7: =I7-G7 -> 800 | L7: =I7/G7 -> 1.0063644 | M7: =I7/F7 -> 1.0063644 | N7: =F7/E7 -> #DIV/0!
B8: B2 | C8: 时光城项目 | D8: 从软件直接取数或统计明细 | F8: 420800 | G8: 420800 | I8: 396605 | J8: =I8/$I$6 -> 0.017904027 | K8: =I8-G8 -> -24195 | L8: =I8/G8 -> 0.94250238 | M8: =I8/F8 -> 0.94250238 | N8: =F8/E8 -> #DIV/0!
B9: B3 | C9: 威高广场项目 | D9: 从软件直接取数或统计明细 | F9: 15315532 | G9: 15315532 | I9: 14276057 | J9: =I9/$I$6 -> 0.64446717 | K9: =I9-G9 -> -1039475.7 | L9: =I9/G9 -> 0.93212931 | M9: =I9/F9 -> 0.93212931 | N9: =F9/E9 -> #DIV/0!
B10: B | C10: 费用合计 | D10: B=B1+B2+B3+.....+Bn | F10: =SUM(F7:F9) -> 15862032 | G10: =SUM(G7:G9) -> 15862032 | I10: =SUM(I7:I9) -> 14799162 | K10: =I10-G10 -> -1062870.7 | L10: =I10/G10 -> 0.93299278 | M10: =I10/F10 -> 0.93299278 | N10: =F10/E10 -> #DIV/0!
A11: 附加价值部分 | B11: E | C11: 结算收益（总附加价值） | D11: E=C-D | F11: =F6-F10 -> 5299337.4 | G11: =G6-G10 -> 5309437.4 | I11: =I6-I10 -> 7352559 | N11: =F11/E11 -> #DIV/0!
A12: 时间 | B12: F1 | C12: 正常出勤时间 | D12: 从软件直接取数或统计明细 | F12: 53899 | G12: 53899 | I12: 53397.5 | K12: =I12-G12 -> -501.5
B13: F2 | C13: 加班时间 | D13: 从软件直接取数或统计明细 | F13: 5959 | G13: 5959 | I13: 5318.5 | K13: =I13-G13 -> -640.5
B14: F | C14: 总时间 | D14: F=F1+F2+F3 | F14: =SUM(F12:F13) -> 59858 | G14: =SUM(G12:G13) -> 59858 | I14: =SUM(I12:I13) -> 58716 | K14: =I14-G14 -> -1142
A15: 单位时间附加值部分 | B15: G | C15: 单位时间附加价值 | D15: G=E/F | F15: =F11/F14 -> 88.531816 | G15: =G11/G14 -> 88.700548 | H15: =H11/H14 -> #DIV/0! | I15: =I11/I14 -> 125.22241 | K15: =I15-G15 -> 36.521861
A16: 其他（根据自家企业特点自行添加）主要是做好余额管理 | B16: J | C16: 人数 | D16: 从软件直接取数或统计明细 | F16: 293 | G16: 293
B17: K | D17: 直接取数 | J17: —— | L17: =I17/G17 -> #DIV/0! | M17: =I17/F17 -> #DIV/0!
B18: L | D18: L=A/J | L18: =I18/G18 -> #DIV/0! | M18: =I18/F18 -> #DIV/0!
B19: M | D19: 盘点表 | L19: =I19/G19 -> #DIV/0! | M19: =I19/F19 -> #DIV/0!
A20: 以下为企业经营者及高管需要掌握的信息(根据企业情况而定）
A21: 核算表栏外部分（经营者及管理层需要掌握） | B21: N | C21: 人工费 | D21: 从软件直接取数或工资表+福利 | E21: 1993071.3 | F21: 1922814.6 | G21: 1922814.6 | I21: 2304821.2
B22: O | C22: 税前利润 | D22: 0=E-N | H22: —— | J22: ——
B23: P | C23: 税前利润率 | D23: P=0/A *100% | H23: —— | J23: ——
B24: Q | C24: 单位时间人工费 | D24: Q=N/F | H24: —— | I24: =I21/I14 -> 39.253717 | J24: ——

Sheet 威高广场1月实际
A1: 威高广场整体核算表（1月实际）
A2: 项目 | D2: 计算公式 | E2: 1月份完成情况 | F2: 月度预算 | G2: 月度预定 | H2: 销售额占比 | I2: 月度实际 | J2: 销售额占比 | K2: 预实差异额 | L2: 预实完成比 | M2: 实际完成预算比 | N2: 2月预定/1月完成
A3: 销售最大化 | B3: A馆 | D3: A1 | F3: 8976177.2 | G3: 8976177.2 | H3: =F3/$F$6 -> 0.60312067 | I3: 9617216.9 | J3: =I3/$I$15 -> 0.45500658 | K3: =I3-G3 -> 641039.79 | L3: =I3/G3 -> 1.0714157
B4: B馆 | D4: A2 | F4: 3340552.6 | G4: 3340552.6 | H4: =F4/$F$6 -> 0.22445594 | I4: 3441935.9 | J4: =I4/$I$15 -> 0.16284373 | K4: =I4-G4 -> 101383.35 | L4: =I4/G4 -> 1.0303493
B5: C馆 | D5: A3 | F5: 2566157.9 | G5: 2566157.9 | H5: =F5/$F$6 -> 0.17242338 | I5: 2563456.5 | J5: =I5/$I$15 -> 0.12128141 | K5: =I5-G5 -> -2701.35 | L5: =I5/G5 -> 0.99894732
B6: 租赁版块小计 | F6: =SUM(F3:F5) -> 14882888 | G6: =SUM(G3:G5) -> 14882888 | H6: =F6/$F$6 -> 1 | I6: =SUM(I3:I5) -> 15622609 | J6: =I6/$I$15 -> 0.73913172 | K6: =SUM(K3:K5) -> 739721.79 | L6: =I6/G6 -> 1.0497028
B7: 停车场收入 | D7: A4 | F7: 1177600 | G7: 1177600 | H7: =F7/$F$6 -> 0.07912443 | I7: 984634 | J7: =I7/$I$15 -> 0.046584678 | K7: =I7-G7 -> -192966 | L7: =I7/G7 -> 0.83613621
B8: 其他收入 | D8: A5 | F8: 385100 | G8: 385100 | H8: =F8/$F$6 -> 0.025875355 | I8: 740873.15 | J8: =I8/$I$15 -> 0.035051945 | K8: =I8-G8 -> 355773.15 | L8: =I8/G8 -> 1.9238461
B9: 餐饮部 | D9: A6 | F9: 382300 | G9: 390000 | H9: =F9/$F$6 -> 0.025687219 | I9: 358800 | J9: =I9/$I$15 -> 0.016975427 | K9: =I9-G9 -> -31200 | L9: =I9/G9 -> 0.92
B10: 写字楼 | D10: A7 | F10: 459300 | G10: 459300 | H10: =F10/$F$6 -> 0.030860947 | I10: 434300 | J10: =I10/$I$15 -> 0.020547458 | K10: =I10-G10 -> -25000 | L10: =I10/G10 -> 0.94556934
B11: 酒店及配套 | D11: A8 | F11: 492433.89 | G11: 492433.89 | H11: =F11/$F$6 -> 0.033087254 | I11: 492433.89 | J11: =I11/$I$15 -> 0.023297869 | K11: =I11-G11 -> 0 | L11: =I11/G11 -> 1
B12: 能源收入 | D12: A9 | F12: 2067481 | G12: 2067481 | H12: =F12/$F$6 -> 0.13891666 | I12: 2206885 | J12: =I12/$I$15 -> 0.10441141 | K12: =I12-G12 -> 139404 | L12: =I12/G12 -> 1.067427
B13: 推广收入 | D13: A10 | F13: 183700 | G13: 190600 | H13: =F13/$F$6 -> 0.012343035 | I13: 219600 | J13: =I13/$I$15 -> 0.010389642 | K13: =I13-G13 -> 29000 | L13: =I13/G13 -> 1.1521511
B14: 开乐影城 | D14: A11 | F14: 105614.67 | G14: 105614.67 | H14: =F14/$F$6 -> 0.0070963829 | I14: 76299.27 | J14: =I14/$I$15 -> 0.0036098458 | K14: =I14-G14 -> -29315.4 | L14: =I14/G14 -> 0.72243061
A15: 总收入金额 | D15: A=A1+...A6 | F15: =SUM(F6:F14) -> 20136417 | G15: =SUM(G6:G14) -> 20151017 | I15: =SUM(I6:I14) -> 21136435 | K15: =SUM(K6:K14) -> 985417.54 | L15: =I15/G15 -> 1.0489016
B16: 年度销售额累计 | J16: =I16/$I$15 -> 0
A17: 费用最小化 | B17: 财务费用（利息） | D17: F1 | F17: 9456669 | G17: 9456669 | H17: =G17/$G$15 -> 0.46928991 | I17: 8982059.5 | J17: =I17/$I$15 -> 0.42495622 | K17: =I17-G17 -> -474609.51 | L17: =I17/G17 -> 0.94981219
B18: 商户能源费 | D18: F2 | F18: 1879529 | G18: 1879529 | H18: =G18/$G$15 -> 0.093272165 | I18: 1931025 | J18: =I18/$I$15 -> 0.091360015 | K18: =I18-G18 -> 51496 | L18: =I18/G18 -> 1.0273984
B19: 公区能源费 | D19: F3 | F19: 1889700 | G19: 1789985 | H19: =G19/$G$15 -> 0.088828518 | I19: 1633812 | J19: =I19/$I$15 -> 0.077298372 | K19: =I19-G19 -> -156173 | L19: =I19/G19 -> 0.91275178
B20: 推广费 | D20: F4 | F20: 457182.5 | G20: 452182.5 | H20: =G20/$G$15 -> 0.022439686 | I20: 566899.39 | J20: =I20/$I$15 -> 0.026820956 | K20: =I20-G20 -> 114716.89 | L20: =I20/G20 -> 1.253696
B21: 外包费用 | D21: F5 | F21: 517775.66 | G21: 517775.66 | H21: =G21/$G$15 -> 0.025694765 | I21: 517775.66 | J21: =I21/$I$15 -> 0.024496831 | K21: =I21-G21 -> 0 | L21: =I21/G21 -> 1
B22: 修理费 | D22: F6 | F22: 332500 | G22: 332500 | H22: =G22/$G$15 -> 0.016500408 | I22: 200122 | J22: =I22/$I$15 -> 0.0094681058 | K22: =I22-G22 -> -132378 | L22: =I22/G22 -> 0.60187068
B23: 维保费 | D23: F7 | F23: 179088 | G23: 179088 | H23: =G23/$G$15 -> 0.0088872933 | I23: 210429 | J23: =I23/$I$15 -> 0.0099557472 | K23: =I23-G23 -> 31341 | L23: =I23/G23 -> 1.1750034
B24: 法律事务费 | D24: F8 | F24: 10000 | G24: 10000 | H24: =G24/$G$15 -> 0.00049625286 | I24: 0 | J24: =I24/$I$15 -> 0 | K24: =I24-G24 -> -10000 | L24: =I24/G24 -> 0
B25: 招商配套费 | D25: F10 | F25: 4720 | G25: 4720 | H25: =G25/$G$15 -> 0.00023423135 | I25: 18000 | J25: =I25/$I$15 -> 0.00085161004 | K25: =I25-G25 -> 13280 | L25: =I25/G25 -> 3.8135593
B26: 财务费用（保险） | D26: F11 | F26: 67200 | G26: 67200 | H26: =G26/$G$15 -> 0.0033348193 | I26: 67200 | J26: =I26/$I$15 -> 0.0031793441 | K26: =I26-G26 -> 0 | L26: =I26/G26 -> 1
B27: 摊销费用（日常摊销） | D27: F12 | F27: 43600 | G27: 43600 | H27: =G27/$G$15 -> 0.0021636625 | I27: 33758.47 | J27: =I27/$I$15 -> 0.0015971696 | K27: =I27-G27 -> -9841.53 | L27: =I27/G27 -> 0.77427683
B28: 业务招待费 | D28: F13 | F28: 239500 | G28: 239500 | H28: =G28/$G$15 -> 0.011885256 | I28: 4523.38 | J28: =I28/$I$15 -> 0.00021400866 | K28: =I28-G28 -> -234976.62 | L28: =I28/G28 -> 0.018886764
B29: 折旧费（固定资产） | D29: F14 | F29: 36400 | G29: 36400 | H29: =G29/$G$15 -> 0.0018063604 | I29: =23510.75+13322.47-5018.36-846.19 -> 30968.67 | J29: =I29/$I$15 -> 0.0014651795 | K29: =I29-G29 -> -5431.33 | L29: =I29/G29 -> 0.85078764
B30: 差旅费 | D30: F15 | F30: 15400 | G30: 15400 | H30: =G30/$G$15 -> 0.00076422941 | I30: =4030.47 -> 4030.47 | J30: =I30/$I$15 -> 0.00019068826 | K30: =I30-G30 -> -11369.53 | L30: =I30/G30 -> 0.26171883
B31: 办公费用 | D31: F16 | F31: 138400 | G31: 138400 | H31: =G31/$G$15 -> 0.0068681396 | I31: =2425.02 -> 2425.02 | J31: =I31/$I$15 -> 0.00011473174 | K31: =I31-G31 -> -135974.98 | L31: =I31/G31 -> 0.017521821
B32: 通讯费 | D32: F17 | F32: 3600 | G32: 3600 | H32: =G32/$G$15 -> 0.00017865103 | I32: =12922.14+681.87+146.32 -> 13750.33 | J32: =I32/$I$15 -> 0.00065055106 | K32: =I32-G32 -> 10150.33 | L32: =I32/G32 -> 3.8195361
B33: 网络费 | D33: F18 | F33: 105000 | G33: 105000 | H33: =G33/$G$15 -> 0.0052106551 | I33: 8387 | J33: =I33/$I$15 -> 0.00039680297 | K33: =I33-G33 -> -96613 | L33: =I33/G33 -> 0.07987619
B34: 对客服务费 | D34: F19 | F34: 52897 | G34: 48150 | H34: =G34/$G$15 -> 0.0023894575 | I34: 50890.9 | J34: =I34/$I$15 -> 0.0024077334 | K34: =I34-G34 -> 2740.9 | L34: =I34/G34 -> 1.0569242
A35: 费用合计 | D35: G | F35: =SUM(F17:F34) -> 15429161 | G35: =SUM(G17:G34) -> 15319699 | I35: =SUM(I17:I34) -> 14276057 | K35: =SUM(K17:K34) -> -1043642.4
A36: 结算收益（附加价值） | D36: I=A-G | F36: =F15-F35 -> 4707256 | G36: =G15-G35 -> 4831318 | I36: =I15-I35 -> 6860377.9 | J36: =J15-J35 -> 0 | K36: =K15-K35 -> 2029059.9
A37: 效率最大化 | B37: 平均总投入人员（个） | C37: 正常人员 | D37: L1 | E37: 1993071.3 | F37: 258 | G37: 258 | I37: 258 | K37: =I37-G37 -> 0 | L37: =I37/G37 -> 1 | M37: =I37/F37 -> 1
C38: 新增人员 | D38: L2 | E38: 0 | F38: 0 | G38: 0 | I38: 0 | K38: =I38-G38 -> 0 | L38: 0 | M38: 0
C39: 总人员合计 | D39: L=L1+L2 | E39: =SUM(E37:E38) -> 1993071.3 | F39: =SUM(F37:F38) -> 258 | G39: =SUM(G37:G38) -> 258 | I39: =SUM(I37:I38) -> 258 | K39: =I39-G39 -> 0 | L39: =I39/G39 -> 1 | M39: =I39/F39 -> 1
B40: 总时间（小时） | C40: 正常时间 | D40: M1 | E40: 42037.8 | F40: 47459 | G40: 47459 | I40: 47174.5 | K40: =I40-G40 -> -284.5 | L40: =I40/G40 -> 0.99400535 | M40: =I40/F40 -> 0.99400535
...

Sheet 威高广场推移表
A1: 威高广场2026年度推移表
B2: 科目 | H2: 1月 | O2: 2月 | V2: 3月 | AC2: 4月 | AJ2: 5月 | AQ2: 6月 | AX2: 7月 | BE2: 8月 | BL2: 9月 | BS2: 10月 | BZ2: 11月 | CG2: 12月
C3: 计算公式 | D3: 2025年度实际 | E3: 2026年度预算 | F3: 2026年度实际累计达成 | G3: 2026年度计划累计达成率 % | H3: 月度预算 | I3: 月度预定 | J3: 月度实绩 | K3: 销售额 占比 | L3: 预实差 | M3: （实绩达成） 预定比率 | N3: 月度MP比 | O3: 月度预算 | P3: 月度预定 | Q3: 月度实绩 | R3: 销售额 占比 | S3: 预实差 | T3: （实绩达成） 预定比率 | U3: 月度MP比 | V3: 月度预算 | W3: 月度预定 | X3: 月度实绩 | Y3: 销售额 占比 | Z3: 预实差 | AA3: （实绩达成） 预定比率 | AB3: 月度MP比 | AC3: 月度预算 | AD3: 月度预定 | AE3: 月度实绩 | AF3: 销售额 占比 | AG3: 预实差 | AH3: （实绩达成） 预定比率 | AI3: 月度MP比 | AJ3: 月度预算 | AK3: 月度预定 | AL3: 月度实绩 | AM3: 销售额 占比 | AN3: 预实差 | AO3: （实绩达成） 预定比率 | AP3: 月度MP比 | AQ3: 月度预算 | AR3: 月度预定 | AS3: 月度实绩 | AT3: 销售额 占比 | AU3: 预实差 | AV3: （实绩达成） 预定比率 | AW3: 月度MP比 | AX3: 月度预算 | AY3: 月度预定 | AZ3: 月度实绩 | BA3: 销售额 占比 | BB3: 预实差 | BC3: （实绩达成） 预定比率 | BD3: 月度MP比 | BE3: 月度预算 | BF3: 月度预定 | BG3: 月度实绩 | BH3: 销售额 占比 | BI3: 预实差 | BJ3: （实绩达成） 预定比率 | BK3: 月度MP比 | BL3: 月度预算 | BM3: 月度预定 | BN3: 月度实绩 | BO3: 销售额 占比 | BP3: 预实差 | BQ3: （实绩达成） 预定比率 | BR3: 月度MP比 | BS3: 月度预算 | BT3: 月度预定 | BU3: 月度实绩 | BV3: 销售额 占比 | BW3: 预实差 | BX3: （实绩达成） 预定比率 | BY3: 月度MP比 | BZ3: 月度预算 | CA3: 月度预定 | CB3: 月度实绩 | CC3: 销售额 占比 | CD3: 预实差 | CE3: （实绩达成） 预定比率 | CF3: 月度MP比 | CG3: 月度预算 | CH3: 月度预定 | CI3: 月度实绩 | CJ3: 销售额 占比 | CK3: 预实差 | CL3: （实绩达成） 预定比率 | CM3: 月度MP比
A4: 销 售 最 大 化 | B4: A馆 | C4: A1 | D4: 117533700 | E4: 1.1510844e+08 | F4: =J4+Q4+X4+AE4+AL4+AS4+AZ4+BG4+BN4+BU4+CB4+CI4 -> 18979032 | G4: =F4/E4 -> 0.16487959 | H4: 8976177.2 | I4: 8976177.2 | J4: =威高广场1月实际!I3 -> 9617216.9 | K4: =J4/$J$16 -> 0.45500658 | L4: =J4-I4 -> 641039.79 | M4: =J4/I4 -> 1.0714157 | N4: =J4/H4 -> 1.0714157 | O4: =威高广场2月实际!F3 -> 9150810.1 | P4: =威高广场2月实际!G3 -> 9150810.1 | Q4: =威高广场2月实际!I3 -> 9361815.3 | S4: =威高广场2月实际!K3 -> 211005.26 | T4: =Q4/P4 -> 1.0230586 | U4: =Q4/O4 -> 1.0230586 | V4: =威高广场3月实际!F3 -> 10060063 | W4: =威高广场3月实际!G3 -> 10060063 | CJ4: =CI4/$AZ$16 -> #DIV/0! | CK4: =CI4-CH4 -> 0 | CL4: =CI4/CH4 -> #DIV/0! | CM4: =CI4/CG4 -> #DIV/0!
B5: B馆 | C5: A2 | D5: 42491600 | E5: 42494624 | F5: =J5+Q5+X5+AE5+AL5+AS5+AZ5+BG5+BN5+BU5+CB5+CI5 -> 6965525 | G5: =F5/E5 -> 0.16391544 | H5: 3340552.6 | I5: 3340552.6 | J5: =威高广场1月实际!I4 -> 3441935.9 | K5: =J5/$J$16 -> 0.16284373 | L5: =J5-I5 -> 101383.35 | M5: =J5/I5 -> 1.0303493 | N5: =J5/H5 -> 1.0303493 | O5: =威高广场2月实际!F4 -> 2946632.8 | P5: =威高广场2月实际!G4 -> 2946632.8 | Q5: =威高广场2月实际!I4 -> 3523589 | S5: =威高广场2月实际!K4 -> 576956.21 | T5: =Q5/P5 -> 1.1958019 | U5: =Q5/O5 -> 1.1958019 | V5: =威高广场3月实际!F4 -> 4466249.9 | W5: =威高广场3月实际!G4 -> 4466249.9 | CJ5: =CI5/$AZ$16 -> #DIV/0! | CK5: =CI5-CH5 -> 0 | CL5: =CI5/CH5 -> #DIV/0! | CM5: =CI5/CG5 -> #DIV/0!
B6: C馆 | C6: A3 | D6: 36293300 | E6: 35155290 | F6: =J6+Q6+X6+AE6+AL6+AS6+AZ6+BG6+BN6+BU6+CB6+CI6 -> 5047496.9 | G6: =F6/E6 -> 0.14357716 | H6: 2566157.9 | I6: 2566157.9 | J6: =威高广场1月实际!I5 -> 2563456.5 | K6: =J6/$J$16 -> 0.12128141 | L6: =J6-I6 -> -2701.35 | M6: =J6/I6 -> 0.99894732 | N6: =J6/H6 -> 0.99894732 | O6: =威高广场2月实际!F5 -> 2586876.1 | P6: =威高广场2月实际!G5 -> 2586876.1 | Q6: =威高广场2月实际!I5 -> 2484040.4 | S6: =威高广场2月实际!K5 -> -102835.69 | T6: =Q6/P6 -> 0.96024715 | U6: =Q6/O6 -> 0.96024715 | V6: =威高广场3月实际!F5 -> 2277375.8 | W6: =威高广场3月实际!G5 -> 2277375.8 | CJ6: =CI6/$AZ$16 -> #DIV/0! | CK6: =CI6-CH6 -> 0 | CL6: =CI6/CH6 -> #DIV/0! | CM6: =CI6/CG6 -> #DIV/0!
B7: 租赁小计 | D7: =SUM(D4:D6) -> 196318600 | E7: =SUM(E4:E6) -> 1.9275835e+08 | F7: =J7+Q7+X7+AE7+AL7+AS7+AZ7+BG7+BN7+BU7+CB7+CI7 -> 30992054 | G7: =F7/E7 -> 0.1607819 | H7: =SUM(H4:H6) -> 14882888 | I7: =SUM(I4:I6) -> 14882888 | J7: =SUM(J4:J6) -> 15622609 | K7: =J7/$J$16 -> 0.73913172 | L7: =J7-I7 -> 739721.79 | M7: =J7/I7 -> 1.0497028 | N7: =J7/H7 -> 1.0497028 | O7: =SUM(O4:O6) -> 14684319 | P7: =SUM(P4:P6) -> 14684319 | Q7: =威高广场2月实际!I6 -> 15369445 | S7: =SUM(S4:S6) -> 685125.78 | T7: =Q7/P7 -> 1.046657 | U7: =Q7/O7 -> 1.046657 | V7: =SUM(V4:V6) -> 16803689 | W7: =SUM(W4:W6) -> 16803689
B8: 停车场收入 | C8: A4 | D8: 10812575 | E8: 10770000 | F8: =J8+Q8+X8+AE8+AL8+AS8+AZ8+BG8+BN8+BU8+CB8+CI8 -> 2086437 | G8: =F8/E8 -> 0.19372674 | H8: 1177600 | I8: 1177600 | J8: =威高广场1月实际!I7 -> 984634 | K8: =J8/$J$16 -> 0.046584678 | L8: =J8-I8 -> -192966 | M8: =J8/I8 -> 0.83613621 | N8: =J8/H8 -> 0.83613621 | O8: =威高广场2月实际!F7 -> 1347000 | P8: =威高广场2月实际!G7 -> 1347000 | Q8: =威高广场2月实际!I7 -> 1101803 | S8: =威高广场2月实际!K7 -> -245197 | T8: =Q8/P8 -> 0.81796808 | U8: =Q8/O8 -> 0.81796808 | V8: =威高广场3月实际!F7 -> 1015400 | W8: =威高广场3月实际!G7 -> 1015400 | CJ8: =CI8/$AZ$16 -> #DIV/0! | CK8: =CI8-CH8 -> 0 | CL8: =CI8/CH8 -> #DIV/0! | CM8: =CI8/CG8 -> #DIV/0!
B9: 其他收入 | C9: A5 | D9: 1946894.8 | E9: 2793600 | F9: =J9+Q9+X9+AE9+AL9+AS9+AZ9+BG9+BN9+BU9+CB9+CI9 -> 379863.48 | G9: =F9/E9 -> 0.13597633 | H9: 385100 | I9: 385100 | J9: =威高广场1月实际!I8 -> 740873.15 | K9: =J9/$J$16 -> 0.035051945 | L9: =J9-I9 -> 355773.15 | M9: =J9/I9 -> 1.9238461 | N9: =J9/H9 -> 1.9238461 | O9: =威高广场2月实际!F8 -> 233700 | P9: =威高广场2月实际!G8 -> 233700 | Q9: =威高广场2月实际!I8 -> -361009.67 | S9: =威高广场2月实际!K8 -> -594709.67 | T9: =Q9/P9 -> -1.5447568 | U9: =Q9/O9 -> -1.5447568 | V9: =威高广场3月实际!F8 -> 100400 | W9: =威高广场3月实际!G8 -> 100400 | CJ9: =CI9/$AZ$16 -> #DIV/0! | CK9: =CI9-CH9 -> 0 | CL9: =CI9/CH9 -> #DIV/0! | CM9: =CI9/CG9 -> #DIV/0!
B10: 餐饮部 | C10: A6 | D10: 4141700 | E10: 4327900 | F10: =J10+Q10+X10+AE10+AL10+AS10+AZ10+BG10+BN10+BU10+CB10+CI10 -> 791400 | G10: =F10/E10 -> 0.18286005 | H10: 382300 | I10: 390000 | J10: =威高广场1月实际!I9 -> 358800 | K10: =J10/$J$16 -> 0.016975427 | L10: =J10-I10 -> -31200 | M10: =J10/I10 -> 0.92 | N10: =J10/H10 -> 0.93852995 | O10: =威高广场2月实际!F9 -> 473000 | P10: =威高广场2月实际!G9 -> 473000 | Q10: =威高广场2月实际!I9 -> 432600 | S10: =威高广场2月实际!K9 -> -40400 | T10: =Q10/P10 -> 0.91458774 | U10: =Q10/O10 -> 0.91458774 | V10: =威高广场3月实际!F9 -> 294000 | W10: =威高广场3月实际!G9 -> 294000
B11: 写字楼 | C11: A7 | D11: 5768603 | E11: 5981400 | F11: =J11+Q11+X11+AE11+AL11+AS11+AZ11+BG11+BN11+BU11+CB11+CI11 -> 867300 | G11: =F11/E11 -> 0.1449995 | H11: 455800 | I11: 455800 | J11: =威高广场1月实际!I10 -> 434300 | K11: =J11/$J$16 -> 0.020547458 | L11: =J11-I11 -> -21500 | M11: =J11/I11 -> 0.95283019 | N11: =J11/H11 -> 0.95283019 | O11: 459300 | P11: =威高广场2月实际!G10 -> 459300 | Q11: =威高广场2月实际!I10 -> 433000 | S11: =威高广场2月实际!K10 -> -26300 | T11: =Q11/P11 -> 0.94273895 | U11: =Q11/O11 -> 0.94273895 | V11: =威高广场3月实际!F10 -> 459300 | W11: =威高广场3月实际!G10 -> 459300 | CJ11: =CI11/$AZ$16 -> #DIV/0! | CK11: =CI11-CH11 -> 0 | CL11: =CI11/CH11 -> #DIV/0! | CM11: =CI11/CG11 -> #DIV/0!
B12: 酒店及配套 | C12: A8 | D12: 4166666.9 | E12: 6690280.3 | F12: =J12+Q12+X12+AE12+AL12+AS12+AZ12+BG12+BN12+BU12+CB12+CI12 -> 984867.46 | G12: =F12/E12 -> 0.1472087 | H12: 492433.89 | I12: 492433.89 | J12: =威高广场1月实际!I11 -> 492433.89 | K12: =J12/$J$16 -> 0.023297869 | L12: =J12-I12 -> 0 | M12: =J12/I12 -> 1 | N12: =J12/H12 -> 1 | O12: =威高广场2月实际!F11 -> 492433.89 | P12: =威高广场2月实际!G11 -> 492433.89 | Q12: =威高广场2月实际!I11 -> 492433.57 | S12: =威高广场2月实际!K11 -> -0.32 | T12: =Q12/P12 -> 0.99999935 | U12: =Q12/O12 -> 0.99999935 | V12: =威高广场3月实际!F11 -> 492433.89 | W12: =威高广场3月实际!G11 -> 492433.89 | CJ12: =CI12/$AZ$16 -> #DIV/0! | CK12: =CI12-CH12 -> 0 | CL12: =CI12/CH12 -> #DIV/0! | CM12: =CI12/CG12 -> #DIV/0!
B13: 能源收入 | C13: A9 | D13: 5052350 | E13: 27100507 | F13: =J13+Q13+X13+AE13+AL13+AS13+AZ13+BG13+BN13+BU13+CB13+CI13 -> 4680569 | G13: =F13/E13 -> 0.17271149 | H13: 2067481 | I13: 2067481 | J13: =威高广场1月实际!I12 -> 2206885 | K13: =J13/$J$16 -> 0.10441141 | L13: =J13-I13 -> 139404 | M13: =J13/I13 -> 1.067427 | N13: =J13/H13 -> 1.067427 | O13: =威高广场2月实际!F12 -> 1916800 | P13: =威高广场2月实际!G12 -> 2219654 | Q13: =威高广场2月实际!I12 -> 2473684 | S13: =威高广场2月实际!K12 -> 254030 | T13: =Q13/P13 -> 1.1144458 | U13: =Q13/O13 -> 1.290528 | V13: =威高广场3月实际!F12 -> 1986541 | W13: =威高广场3月实际!G12 -> 1965698 | CJ13: =CI13/$AZ$16 -> #DIV/0! | CK13: =CI13-CH13 -> 0 | CL13: =CI13/CH13 -> #DIV/0! | CM13: =CI13/CG13 -> #DIV/0!
B14: 推广收入 | C14: A10 | D14: 2736729.1 | E14: 2520000 | F14: =J14+Q14+X14+AE14+AL14+AS14+AZ14+BG14+BN14+BU14+CB14+CI14 -> 441300 | G14: =F14/E14 -> 0.17511905 | H14: 183700 | I14: 190600 | J14: =威高广场1月实际!I13 -> 219600 | K14: =J14/$J$16 -> 0.010389642 | L14: =J14-I14 -> 29000 | M14: =J14/I14 -> 1.1521511 | N14: =J14/H14 -> 1.1954273 | O14: =威高广场2月实际!F13 -> 176300 | P14: =威高广场2月实际!G13 -> 176300 | Q14: =威高广场2月实际!I13 -> 221700 | S14: =威高广场2月实际!K13 -> 45400 | T14: =Q14/P14 -> 1.2575156 | U14: =Q14/O14 -> 1.2575156 | V14: =威高广场3月实际!F13 -> 163300 | W14: =威高广场3月实际!G13 -> 163300 | CJ14: =CI14/$AZ$16 -> #DIV/0! | CK14: =CI14-CH14 -> 0 | CL14: =CI14/CH14 -> #DIV/0! | CM14: =CI14/CG14 -> #DIV/0!
B15: 开乐影城 | C15: A11 | D15: 3000742.4 | E15: 2250000 | F15: =J15+Q15+X15+AE15+AL15+AS15+AZ15+BG15+BN15+BU15+CB15+CI15 -> 854614.09 | G15: =F15/E15 -> 0.37982848 | H15: 105614.67 | I15: 105614.67 | J15: =威高广场1月实际!I14 -> 76299.27 | K15: =J15/$J$16 -> 0.0036098458 | L15: =J15-I15 -> -29315.4 | M15: =J15/I15 -> 0.72243061 | N15: =J15/H15 -> 0.72243061 | O15: =威高广场2月实际!F14 -> 696354.13 | P15: =威高广场2月实际!G14 -> 696354.13 | Q15: =威高广场2月实际!I14 -> 778314.82 | S15: =威高广场2月实际!K14 -> 81960.693 | T15: =Q15/P15 -> 1.1176997 | U15: =Q15/O15 -> 1.1176997 | V15: =威高广场3月实际!F14 -> 81436.438 | W15: =威高广场3月实际!G14 -> 81436.438 | CJ15: =CI15/$AZ$16 -> #DIV/0! | CK15: =CI15-CH15 -> 0 | CL15: =CI15/CH15 -> #DIV/0! | CM15: =CI15/CG15 -> #DIV/0!
A16: 总销售金额 | C16: A=A1+… | D16: =SUM(D7:D15) -> 2.3394486e+08 | E16: =SUM(E4:E9) -> 3.9908031e+08 | F16: =SUM(F7:F15) -> 42078405 | G16: =F16/E16 -> 0.10543844 | H16: =SUM(H7:H15) -> 20132917 | I16: =SUM(I7:I15) -> 20147517 | J16: =SUM(J7:J15) -> 21136435 | L16: =J16-I16 -> 988917.54 | M16: =J16/I16 -> 1.0490838 | N16: =J16/H16 -> 1.0498446 | O16: =SUM(O7:O15) -> 20479207 | P16: =SUM(P7:P15) -> 20782061 | Q16: =SUM(Q7:Q15) -> 20941970 | R16: =Q16/$J$16 -> 0.99079957 | S16: =Q16-P16 -> 159909.48 | T16: =Q16/P16 -> 1.0076946 | U16: =Q16/O16 -> 1.0225967 | V16: =SUM(V7:V15) -> 21396500 | W16: =SUM(W7:W15) -> 21375657 | X16: =SUM(#REF!) -> #REF! | Y16: =X16/$J$16 -> #REF! | Z16: =X16-W16 -> #REF! | AA16: =X16/W16 -> #REF! | AB16: =X16/V16 -> #REF! | AC16: =SUM(#REF!) -> #REF! | AD16: =SUM(#REF!) -> #REF! | AE16: =SUM(#REF!) -> #REF! | AF16: =AE16/$J$16 -> #REF! | AG16: =AE16-AD16 -> #REF! | AH16: =AE16/AD16 -> #REF! | AI16: =AE16/AC16 -> #REF! | AJ16: =SUM(#REF!) -> #REF! | AK16: =SUM(#REF!) -> #REF! | AL16: =SUM(#REF!) -> #REF! | AM16: =AL16/$J$16 -> #REF! | AN16: =AL16-AK16 -> #REF! | AO16: =AL16/AK16 -> #REF! | AP16: =AL16/AJ16 -> #REF! | AQ16: =SUM(#REF!) -> #REF! | AR16: =SUM(#REF!) -> #REF! | AS16: =SUM(#REF!) -> #REF! | AT16: =AS16/$J$16 -> #REF! | AU16: =AS16-AR16 -> #REF! | AV16: =AS16/AR16 -> #REF! | AW16: =AS16/AQ16 -> #REF! | CI16: =SUM(CI4:CI9) -> 0 | CJ16: =CI16/$AZ$16 -> #DIV/0! | CK16: =CI16-CH16 -> 0 | CL16: =CI16/CH16 -> #DIV/0! | CM16: =CI16/CG16 -> #DIV/0!
A17: 费 用 最 小 化 | B17: 财务费用（利息） | C17: F1 | D17: 93926787 | E17: 119109578 | F17: =J17+Q17+X17+AE17+AL17+AS17+AZ17+BG17+BN17+BU17+CB17+CI17 -> 18438728 | G17: =F17/E17 -> 0.15480475 | H17: 9456669 | I17: 9456669 | J17: =威高广场1月实际!I17 -> 8982059.5 | K17: =J17/$J$16 -> 0.42495622 | L17: =J17-I17 -> -474609.51 | M17: =J17/I17 -> 0.94981219 | N17: =J17/H17 -> 0.94981219 | O17: =威高广场2月实际!F17 -> 9456669 | P17: =威高广场2月实际!G17 -> 9456669 | Q17: =威高广场2月实际!I17 -> 9456669 | S17: =Q17-P17 -> 0 | T17: =Q17/P17 -> 1 | U17: =Q17/O17 -> 1 | V17: =威高广场3月实际!F17 -> 9707200 | W17: =威高广场3月实际!G17 -> 9707200 | CJ17: =CI17/$AZ$16 -> #DIV/0! | CK17: =CI17-CH17 -> 0 | CL17: =CI17/CH17 -> #DIV/0! | CM17: =CI17/CG17 -> #DIV/0!
B18: 商户能源费 | C18: F2 | D18: 25404840 | E18: 24636825 | F18: =J18+Q18+X18+AE18+AL18+AS18+AZ18+BG18+BN18+BU18+CB18+CI18 -> 3921599 | G18: =F18/E18 -> 0.15917631 | H18: 1879529 | I18: 1879529 | J18: =威高广场1月实际!I18 -> 1931025 | K18: =J18/$J$16 -> 0.091360015 | L18: =J18-I18 -> 51496 | M18: =J18/I18 -> 1.0273984 | N18: =J18/H18 -> 1.0273984 | O18: =威高广场2月实际!F18 -> 1916800 | P18: =威高广场2月实际!G18 -> 2014569 | Q18: =威高广场2月实际!I18 -> 1990574 | S18: =Q18-P18 -> -23995 | T18: =Q18/P18 -> 0.98808926 | U18: =Q18/O18 -> 1.0384881 | V18: =威高广场3月实际!F18 -> 1695700 | W18: =威高广场3月实际!G18 -> 1695700 | CJ18: =CI18/$AZ$16 -> #DIV/0! | CK18: =CI18-CH18 -> 0 | CL18: =CI18/CH18 -> #DIV/0! | CM18: =CI18/CG18 -> #DIV/0!
B19: 公区能源费 | C19: F3 | D19: 15920720 | E19: 16106800 | F19: =J19+Q19+X19+AE19+AL19+AS19+AZ19+BG19+BN19+BU19+CB19+CI19 -> 2771205 | G19: =F19/E19 -> 0.17205187 | H19: 1889700 | I19: 1889700 | J19: =威高广场1月实际!I19 -> 1633812 | K19: =J19/$J$16 -> 0.077298372 | L19: =J19-I19 -> -255888 | M19: =J19/I19 -> 0.86458803 | N19: =J19/H19 -> 0.86458803 | O19: =威高广场2月实际!F19 -> 1847200 | P19: =威高广场2月实际!G19 -> 1605300 | Q19: =威高广场2月实际!I19 -> 1137393 | S19: =Q19-P19 -> -467907 | T19: =Q19/P19 -> 0.70852364 | U19: =Q19/O19 -> 0.61573896 | V19: =威高广场3月实际!F19 -> 1343400 | W19: =威高广场3月实际!G19 -> 1343400 | CJ19: =CI19/$AZ$16 -> #DIV/0! | CK19: =CI19-CH19 -> 0 | CL19: =CI19/CH19 -> #DIV/0! | CM19: =CI19/CG19 -> #DIV/0!
B20: 推广费 | C20: F4 | D20: 6935000 | E20: 7119800 | F20: =J20+Q20+X20+AE20+AL20+AS20+AZ20+BG20+BN20+BU20+CB20+CI20 -> 1063496.2 | G20: =F20/E20 -> 0.14937165 | H20: 457182.5 | I20: 452182.5 | J20: =威高广场1月实际!I20 -> 566899.39 | K20: =J20/$J$16 -> 0.026820956 | L20: =J20-I20 -> 114716.89 | M20: =J20/I20 -> 1.253696 | N20: =J20/H20 -> 1.2399849 | O20: =威高广场2月实际!F20 -> 265182.5 | P20: =威高广场2月实际!G20 -> 335182.5 | Q20: =威高广场2月实际!I20 -> 496596.85 | S20: =Q20-P20 -> 161414.35 | T20: =Q20/P20 -> 1.4815715 | U20: =Q20/O20 -> 1.8726607 | V20: =威高广场3月实际!F20 -> 659782.5 | W20: =威高广场3月实际!G20 -> 659782.5 | CJ20: =CI20/$AZ$16 -> #DIV/0! | CK20: =CI20-CH20 -> 0 | CL20: =CI20/CH20 -> #DIV/0! | CM20: =CI20/CG20 -> #DIV/0!
B21: 外包费用 | C21: F5 | D21: 6457551.3 | E21: 6584309 | F21: =J21+Q21+X21+AE21+AL21+AS21+AZ21+BG21+BN21+BU21+CB21+CI21 -> 1038224.3 | G21: =F21/E21 -> 0.15768159 | H21: 517775.66 | I21: 517775.66 | J21: =威高广场1月实际!I21 -> 517775.66 | K21: =J21/$J$16 -> 0.024496831 | L21: =J21-I21 -> 0 | M21: =J21/I21 -> 1 | N21: =J21/H21 -> 1 | O21: =威高广场2月实际!F21 -> 520448.66 | P21: =威高广场2月实际!G21 -> 520448.66 | Q21: =威高广场2月实际!I21 -> 520448.66 | S21: =Q21-P21 -> 0 | T21: =Q21/P21 -> 1 | U21: =Q21/O21 -> 1 | V21: =威高广场3月实际!F21 -> 517775.66 | W21: =威高广场3月实际!G21 -> 517775.66 | AC21: 517775.66 | AD21: 517775.66 | CJ21: =CI21/$AZ$16 -> #DIV/0! | CK21: =CI21-CH21 -> 0 | CL21: =CI21/CH21 -> #DIV/0! | CM21: =CI21/CG21 -> #DIV/0!
B22: 修理费 | C22: F6 | D22: 3512402 | E22: 4535000 | F22: =J22+Q22+X22+AE22+AL22+AS22+AZ22+BG22+BN22+BU22+CB22+CI22 -> 323458 | G22: =F22/E22 -> 0.071324807 | H22: 332500 | I22: 332500 | J22: =威高广场1月实际!I22 -> 200122 | K22: =J22/$J$16 -> 0.0094681058 | L22: =J22-I22 -> -132378 | M22: =J22/I22 -> 0.60187068 | N22: =J22/H22 -> 0.60187068 | O22: =威高广场2月实际!F22 -> 291720 | P22: =威高广场2月实际!G22 -> 221500 | Q22: =威高广场2月实际!I22 -> 123336 | S22: =Q22-P22 -> -98164 | T22: =Q22/P22 -> 0.55682167 | U22: =Q22/O22 -> 0.42278898 | V22: =威高广场3月实际!F22 -> 243383 | W22: =威高广场3月实际!G22 -> 243383 | CJ22: =CI22/$AZ$16 -> #DIV/0! | CK22: =CI22-CH22 -> 0 | CL22: =CI22/CH22 -> #DIV/0! | CM22: =CI22/CG22 -> #DIV/0!
B23: 维保费 | C23: F7 | D23: 2133874 | E23: 2676782 | F23: =J23+Q23+X23+AE23+AL23+AS23+AZ23+BG23+BN23+BU23+CB23+CI23 -> 405640.06 | G23: =F23/E23 -> 0.15154019 | H23: 182532 | I23: 182532 | J23: =威高广场1月实际!I23 -> 210429 | K23: =J23/$J$16 -> 0.0099557472 | L23: =J23-I23 -> 27897 | M23: =J23/I23 -> 1.1528335 | N23: =J23/H23 -> 1.1528335 | O23: =威高广场2月实际!F23 -> 210429 | P23: =威高广场2月实际!G23 -> 210429 | Q23: =威高广场2月实际!I23 -> 195211.06 | S23: =Q23-P23 -> -15217.94 | T23: =Q23/P23 -> 0.92768136 | U23: =Q23/O23 -> 0.92768136 | V23: =威高广场3月实际!F23 -> 176365 | W23: =威高广场3月实际!G23 -> 176365 | CJ23: =CI23/$AZ$16 -> #DIV/0! | CK23: =CI23-CH23 -> 0 | CL23: =CI23/CH23 -> #DIV/0! | CM23: =CI23/CG23 -> #DIV/0!
B24: 法律事务费 | C24: F8 | D24: 74053.74 | E24: 97200 | F24: =J24+Q24+X24+AE24+AL24+AS24+AZ24+BG24+BN24+BU24+CB24+CI24 -> 101546 | G24: =F24/E24 -> 1.0447119 | H24: 0 | I24: 0 | J24: =威高广场1月实际!I24 -> 0 | K24: =J24/$J$16 -> 0 | L24: =J24-I24 -> 0 | M24: =J24/I24 -> #DIV/0! | N24: =J24/H24 -> #DIV/0! | O24: =威高广场2月实际!F24 -> 101546 | P24: =威高广场2月实际!G24 -> 101546 | Q24: =威高广场2月实际!I24 -> 101546 | S24: =Q24-P24 -> 0 | T24: =Q24/P24 -> 1 | U24: =Q24/O24 -> 1 | V24: =威高广场3月实际!F24 -> 16800 | W24: =威高广场3月实际!G24 -> 16800 | CJ24: =CI24/$AZ$16 -> #DIV/0! | CK24: =CI24-CH24 -> 0 | CL24: =CI24/CH24 -> #DIV/0! | CM24: =CI24/CG24 -> #DIV/0!
B25: 招商配套费 | C25: F9 | D25: 1233414 | E25: 620786.56 | F25: =J25+Q25+X25+AE25+AL25+AS25+AZ25+BG25+BN25+BU25+CB25+CI25 -> 18000 | G25: =F25/E25 -> 0.028995473 | H25: 4720 | I25: 4720 | J25: =威高广场1月实际!I25 -> 18000 | K25: =J25/$J$16 -> 0.00085161004 | L25: =J25-I25 -> 13280 | M25: =J25/I25 -> 3.8135593 | N25: =J25/H25 -> 3.8135593 | O25: =威高广场2月实际!F25 -> 50509.68 | P25: =威高广场2月实际!G25 -> 50509.68 | Q25: 0 | S25: =Q25-P25 -> -50509.68 | T25: =Q25/P25 -> 0 | U25: =Q25/O25 -> 0 | V25: =威高广场3月实际!F25 -> 99066.42 | W25: =威高广场3月实际!G25 -> 99066.42 | CJ25: =CI25/$AZ$16 -> #DIV/0! | CK25: =CI25-CH25 -> 0 | CL25: =CI25/CH25 -> #DIV/0! | CM25: =CI25/CG25 -> #DIV/0!
B26: 财务费用（保险） | C26: F10 | D26: 630111.34 | E26: 682100 | F26: =J26+Q26+X26+AE26+AL26+AS26+AZ26+BG26+BN26+BU26+CB26+CI26 -> 123100 | G26: =F26/E25 -> 0.19829682 | H26: 67200 | I26: 67200 | J26: =威高广场1月实际!I26 -> 67200 | K26: =J26/$J$16 -> 0.0031793441 | L26: =J26-I26 -> 0 | M26: =J26/I26 -> 1 | N26: =J26/H26 -> 1 | O26: =威高广场2月实际!F26 -> 67200 | P26: =威高广场2月实际!G26 -> 67200 | Q26: =威高广场2月实际!I26 -> 55900 | S26: =Q26-P26 -> -11300 | T26: =Q26/P26 -> 0.83184524 | U26: =Q26/O26 -> 0.83184524 | V26: =威高广场3月实际!F26 -> 55900 | W26: =威高广场3月实际!G26 -> 55900 | CJ26: =CI26/$AZ$16 -> #DIV/0! | CK26: =CI26-CH26 -> 0 | CL26: =CI26/CH26 -> #DIV/0! | CM26: =CI26/CG26 -> #DIV/0!
B27: 摊销费用（日常摊销） | C27: F11 | D27: 648651.75 | E27: 548400 | F27: =J27+Q27+X27+AE27+AL27+AS27+AZ27+BG27+BN27+BU27+CB27+CI27 -> 90874.97 | G27: =F27/E27 -> 0.16570928 | H27: 43600 | I27: 43600 | J27: =威高广场1月实际!I27 -> 33758.47 | K27: =J27/$J$16 -> 0.0015971696 | L27: =J27-I27 -> -9841.53 | M27: =J27/I27 -> 0.77427683 | N27: =J27/H27 -> 0.77427683 | O27: =威高广场2月实际!F27 -> 33200 | P27: =威高广场2月实际!G27 -> 33200 | Q27: =威高广场2月实际!I27 -> 57116.5 | S27: =Q27-P27 -> 23916.5 | T27: =Q27/P27 -> 1.7203765 | U27: =Q27/O27 -> 1.7203765 | V27: =威高广场3月实际!F27 -> 68200 | W27: =威高广场3月实际!G27 -> 68200 | CJ27: =CI27/$AZ$16 -> #DIV/0! | CK27: =CI27-CH27 -> 0 | CL27: =CI27/CH27 -> #DIV/0! | CM27: =CI27/CG27 -> #DIV/0!
B28: 折旧费（固定资产） | C28: F12 | D28: 375135.49 | E28: 462600 | F28: =J28+Q28+X28+AE28+AL28+AS28+AZ28+BG28+BN28+BU28+CB28+CI28 -> 35365.67 | G28: =F28/E28 -> 0.076449784 | H28: 36400 | I28: 36400 | J28: =威高广场1月实际!I29 -> 30968.67 | K28: =J28/$J$16 -> 0.0014651795 | L28: =J28-I28 -> -5431.33 | M28: =J28/I28 -> 0.85078764 | N28: =J28/H28 -> 0.85078764 | O28: =威高广场2月实际!F28 -> 27000 | P28: =威高广场2月实际!G28 -> 27000 | Q28: =威高广场2月实际!I28 -> 4397 | S28: =Q28-P28 -> -22603 | T28: =Q28/P28 -> 0.16285185 | U28: =Q28/O28 -> 0.16285185 | V28: =威高广场3月实际!F28 -> 10900 | W28: =威高广场3月实际!G28 -> 10900 | CJ28: =CI28/$AZ$16 -> #DIV/0! | CK28: =CI28-CH28 -> 0 | CL28: =CI28/CH28 -> #DIV/0! | CM28: =CI28/CG28 -> #DIV/0!
B29: 业务招待费 | C29: F13 | D29: 199055.34 | E29: 239500 | F29: =J29+Q29+X29+AE29+AL29+AS29+AZ29+BG29+BN29+BU29+CB29+CI29 -> 36689.35 | G29: =F29/E29 -> 0.15319144 | H29: 36100 | I29: 36100 | J29: =威高广场1月实际!I28 -> 4523.38 | K29: =J29/$J$16 -> 0.00021400866 | L29: =J29-I29 -> -31576.62 | M29: =J29/I29 -> 0.12530139 | N29: =J29/H29 -> 0.12530139 | O29: =威高广场2月实际!F29 -> 37300 | P29: =威高广场2月实际!G29 -> 37300 | Q29: =威高广场2月实际!I29 -> 32165.97 | S29: =Q29-P29 -> -5134.03 | T29: =Q29/P29 -> 0.86235845 | U29: =Q29/O29 -> 0.86235845 | V29: =威高广场3月实际!F29 -> 38300 | W29: =威高广场3月实际!G29 -> 38300 | CJ29: =CI29/$AZ$16 -> #DIV/0! | CK29: =CI29-CH29 -> 0 | CL29: =CI29/CH29 -> #DIV/0! | CM29: =CI29/CG29 -> #DIV/0!
B30: 差旅费 | C30: F14 | D30: 120056.11 | E30: 201300 | F30: =J30+Q30+X30+AE30+AL30+AS30+AZ30+BG30+BN30+BU30+CB30+CI30 -> 4030.47 | G30: =F30/E30 -> 0.020022206 | H30: 15400 | I30: 15400 | J30: =威高广场1月实际!I30 -> 4030.47 | K30: =J30/$J$16 -> 0.00019068826 | L30: =J30-I30 -> -11369.53 | M30: =J30/I30 -> 0.26171883 | N30: =J30/H30 -> 0.26171883 | O30: =威高广场2月实际!F30 -> 800 | P30: =威高广场2月实际!G30 -> 800 | Q30: =威高广场2月实际!I30 -> 0 | S30: =Q30-P30 -> -800 | T30: =Q30/P30 -> 0 | U30: =Q30/O30 -> 0 | V30: =威高广场3月实际!F30 -> 21600 | W30: =威高广场3月实际!G30 -> 21600 | CJ30: =CI30/$AZ$16 -> #DIV/0! | CK30: =CI30-CH30 -> 0 | CL30: =CI30/CH30 -> #DIV/0! | CM30: =CI30/CG30 -> #DIV/0!
B31: 通讯费 | C31: F15 | D31: 53969.17 | E31: 40900 | F31: =J31+Q31+X31+AE31+AL31+AS31+AZ31+BG31+BN31+BU31+CB31+CI31 -> 15452.33 | G31: =F31/E31 -> 0.37780758 | H31: 3400 | I31: 3400 | J31: =威高广场1月实际!I32 -> 13750.33 | K31: =J31/$J$16 -> 0.00065055106 | L31: =J31-I31 -> 10350.33 | M31: =J31/I31 -> 4.0442147 | N31: =J31/H31 -> 4.0442147 | O31: =威高广场2月实际!F31 -> 14100 | P31: =威高广场2月实际!G31 -> 14100 | Q31: =威高广场2月实际!I31 -> 1702 | S31: =Q31-P31 -> -12398 | T31: =Q31/P31 -> 0.12070922 | U31: =Q31/O31 -> 0.12070922 | V31: =威高广场3月实际!F31 -> 9700 | W31: =威高广场3月实际!G31 -> 9700 | CJ31: =CI31/$AZ$16 -> #DIV/0! | CK31: =CI31-CH31 -> 0 | CL31: =CI31/CH31 -> #DIV/0! | CM31: =CI31/CG31 -> #DIV/0!
B32: 办公费用 | C32: F16 | D32: 134458.33 | E32: 138400 | F32: =J32+Q32+X32+AE32+AL32+AS32+AZ32+BG32+BN32+BU32+CB32+CI32 -> 22489.08 | G32: =F32/E32 -> 0.16249335 | H32: 33800 | I32: 33800 | J32: =威高广场1月实际!I31 -> 2425.02 | K32: =J32/$J$16 -> 0.00011473174 | L32: =J32-I32 -> -31374.98 | M32: =J32/I32 -> 0.071746154 | N32: =J32/H32 -> 0.071746154 | O32: =威高广场2月实际!F32 -> 3400 | P32: =威高广场2月实际!G32 -> 3400 | Q32: =威高广场2月实际!I32 -> 20064.06 | S32: =Q32-P32 -> 16664.06 | T32: =Q32/P32 -> 5.9011941 | U32: =Q32/O32 -> 5.9011941 | V32: =威高广场3月实际!F32 -> 60200 | W32: =威高广场3月实际!G32 -> 60200 | CJ32: =CI32/$AZ$16 -> #DIV/0! | CK32: =CI32-CH32 -> 0 | CL32: =CI32/CH32 -> #DIV/0! | CM32: =CI32/CG32 -> #DIV/0!
B33: 网络费 | C33: F17 | D33: 559700 | E33: 654000 | F33: =J33+Q33+X33+AE33+AL33+AS33+AZ33+BG33+BN33+BU33+CB33+CI33 -> 16774 | G33: =F33/E33 -> 0.025648318 | H33: 105000 | I33: 105000 | J33: =威高广场1月实际!I33 -> 8387 | K33: =J33/$J$16 -> 0.00039680297 | L33: =J33-I33 -> -96613 | M33: =J33/I33 -> 0.07987619 | N33: =J33/H33 -> 0.07987619 | O33: =威高广场2月实际!F33 -> 8387 | P33: =威高广场2月实际!G33 -> 8387 | Q33: =威高广场2月实际!I33 -> 8387 | S33: =Q33-P33 -> 0 | T33: =Q33/P33 -> 1 | U33: =Q33/O33 -> 1 | V33: =威高广场3月实际!F33 -> 8387 | W33: =威高广场3月实际!G33 -> 8387 | CJ33: =CI33/$AZ$16 -> #DIV/0! | CK33: =CI33-CH33 -> 0 | CL33: =CI33/CH33 -> #DIV/0! | CM33: =CI33/CG33 -> #DIV/0!
B34: 对客服务费 | C34: F18 | D34: 146968.32 | E34: 447797 | F34: =J34+Q34+X34+AE34+AL34+AS34+AZ34+BG34+BN34+BU34+CB34+CI34 -> 73679.8 | G34: =F34/E34 -> 0.1645384 | H34: 52897 | I34: 48150 | J34: =威高广场1月实际!I34 -> 50890.9 | K34: =J34/$J$16 -> 0.0024077334 | L34: =J34-I34 -> 2740.9 | M34: =J34/I34 -> 1.0569242 | N34: =J34/H34 -> 0.96207535 | O34: 5700 | P34: 31078.9 | Q34: =威高广场2月实际!I34 -> 22788.9 | S34: =Q34-P34 -> -8290 | T34: =Q34/P34 -> 0.73325954 | U34: =Q34/O34 -> 3.9980526 | V34: =威高广场3月实际!F34 -> 50900 | W34: =威高广场3月实际!G34 -> 29000 | CJ34: =CI34/$AZ$16 -> #DIV/0! | CK34: =CI34-CH34 -> 0 | CL34: =CI34/CH34 -> #DIV/0! | CM34: =CI34/CG34 -> #DIV/0!
A35: 费用合计 | B35: 费用合计 | C35: F=F1+… | D35: =SUM(D17:D34) -> 1.5846675e+08 | E35: =SUM(E17:E34) -> 1.8490208e+08 | F35: =SUM(F17:F34) -> 28500353 | G35: =F35/E35 -> 0.15413755 | H35: =SUM(H17:H34) -> 15114405 | I35: =SUM(I17:I34) -> 15104658 | J35: =SUM(J17:J34) -> 14276057 | L35: =J35-I35 -> -828601.38 | M35: =J35/I35 -> 0.94514266 | N35: =J35/H35 -> 0.94453315 | O35: =SUM(O17:O34) -> 14857592 | P35: =SUM(P17:P34) -> 14738620 | Q35: =SUM(Q17:Q34) -> 14224296 | S35: =SUM(S17:S34) -> -514323.74 | V35: =SUM(V17:V34) -> 14783560 | W35: =SUM(W17:W34) -> 14761660 | CI35: =SUM(CI17:CI33) -> 0 | CJ35: =CI35/$AZ$16 -> #DIV/0! | CK35: =CI35-CH35 -> 0 | CL35: =CI35/CH35 -> #DIV/0! | CM35: =CI35/CG35 -> #DIV/0!
A36: 附加价值 | B36: 结算收益 | C36: C=A-F | E36: =E16-E35 -> 2.1417823e+08 | F36: =F16-F35 -> 13578052 | G36: =F36/E36 -> 0.063396044 | H36: =H16-H35 -> 5018512 | I36: =I16-I35 -> 5042859 | J36: =J16-J35 -> 6860377.9 | K36: =J36/$J$16 -> 0.32457593 | L36: =J36-I36 -> 1817518.9 | M36: =J36/I36 -> 1.3604144 | N36: =J36/H36 -> 1.3670143 | O36: =O16-O35 -> 5621615.2 | P36: =P16-P35 -> 6043441.3 | Q36: =Q16-Q35 -> 6717674.5 | R36: =Q36/$J$16 -> 0.31782439 | S36: =Q36-P36 -> 674233.22 | T36: =Q36/P36 -> 1.1115645 | U36: =Q36/O36 -> 1.1949723 | V36: =V16-V35 -> 6612940.8 | W36: =W16-W35 -> 6613997.8 | X36: =X16-#REF! -> #REF! | Y36: =X36/$J$16 -> #REF! | Z36: =X36-W36 -> #REF! | AA36: =X36/W36 -> #REF! | AB36: =X36/V36 -> #REF! | AC36: =AC16-#REF! -> #REF! | AD36: =AD16-#REF! -> #REF! | AE36: =AE16-#REF! -> #REF! | AF36: =AE36/$J$16 -> #REF! | AG36: =AE36-AD36 -> #REF! | AH36: =AE36/AD36 -> #REF! | AI36: =AE36/AC36 -> #REF! | AJ36: =AJ16-#REF! -> #REF! | AK36: =AK16-#REF! -> #REF! | AL36: =AL16-#REF! -> #REF! | AM36: =AL36/$J$16 -> #REF! | AN36: =AL36-AK36 -> #REF! | AO36: =AL36/AK36 -> #REF! | AP36: =AL36/AJ36 -> #REF! | AQ36: =AQ16-#REF! -> #REF! | AR36: =AR16-#REF! -> #REF! | AS36: =AS16-#REF! -> #REF! | AT36: =AS36/$J$16 -> #REF! | AU36: =AS36-AR36 -> #REF! | AV36: =AS36/AR36 -> #REF! | AW36: =AS36/AQ36 -> #REF! | AX36: =AX16-AX35 -> 0 | AY36: =AY16-AY35 -> 0 | AZ36: =AZ16-AZ35 -> 0 | BA36: —— | BB36: =AZ36-AY36 -> 0 | BC36: =AZ36/AY36 -> #DIV/0! | BD36: =AZ36/AX36 -> #DIV/0! | BE36: =BE16-BE35 -> 0 | BF36: =BF16-BF35 -> 0 | BG36: =BG16-BG35 -> 0 | BH36: —— | BI36: =BG36-BF36 -> 0 | BJ36: =BG36/BF36 -> #DIV/0! | BK36: =BG36/BE36 -> #DIV/0! | BL36: =BL16-BL35 -> 0 | BM36: =BM16-BM35 -> 0 | BN36: =BN16-BN35 -> 0 | BO36: —— | BP36: =BN36-BM36 -> 0 | BQ36: =BN36/BM36 -> #DIV/0! | BR36: =BN36/BL36 -> #DIV/0! | BS36: =BS16-BS35 -> 0 | BT36: =BT16-BT35 -> 0 | BU36: =BU16-BU35 -> 0 | BV36: —— | BW36: =BU36-BT36 -> 0 | BX36: =BU36/BT36 -> #DIV/0! | BY36: =BU36/BS36 -> #DIV/0! | BZ36: =BZ16-BZ35 -> 0 | CA36: =CA16-CA35 -> 0 | CB36: =CB16-CB35 -> 0 | CC36: —— | CD36: =CB36-CA36 -> 0 | CE36: =CB36/CA36 -> #DIV/0! | CF36: =CB36/BZ36 -> #DIV/0! | CG36: =CG16-CG35 -> 0 | CH36: =CH16-CH35 -> 0 | CI36: =CI16-CI35 -> 0 | CJ36: —— | CK36: =CI36-CH36 -> 0 | CL36: =CI36/CH36 -> #DIV/0! | CM36: =CI36/CG36 -> #DIV/0!
A37: 效 率 最 大 化 | B37: 正常人员 | C37: L1 | E37: 258 | G37: =F37/E37 -> 0 | H37: 258 | I37: 258 | J37: =威高广场1月实际!I37 -> 258 | K37: —— | L37: =J37-I37 -> 0 | Q37: ='2月时间实际 '!B18 -> 260 | V37: ='3月时间实际'!B18 -> 259 | CJ37: —— | CK37: =CI37-CH37 -> 0 | CL37: =CI37/CH37 -> #DIV/0! | CM37: =CI37/CG37 -> #DIV/0!
B38: 新增人员 | C38: L2 | E38: 0 | G38: =F38/E38 -> #DIV/0! | H38: 0 | I38: 0 | J38: 0 | K38: —— | L38: =J38-I38 -> 0 | O38: 0 | Q38: 0 | V38: 0 | CI38: 0 | CJ38: —— | CK38: =CI38-CH38 -> 0 | CL38: =CI38/CH38 -> #DIV/0! | CM38: =CI38/CG38 -> #DIV/0!
B39: 总人员合计 | C39: L=L1+L2 | E39: =SUM(E37:E38) -> 258 | G39: =F39/E39 -> 0 | H39: =SUM(H37:H38) -> 258 | I39: =SUM(I37:I38) -> 258 | J39: =SUM(J37:J38) -> 258 | K39: —— | L39: =J39-I39 -> 0 | Q39: =SUM(Q37:Q38) -> 260 | V39: =SUM(V37:V38) -> 259 | CI39: =SUM(CI37:CI38) -> 0 | CJ39: —— | CK39: =CI39-CH39 -> 0 | CL39: =CI39/CH39 -> #DIV/0! | CM39: =CI39/CG39 -> #DIV/0!
B40: 正常时间 | C40: M1 | D40: 543554.9 | E40: 543554.9 | F40: =J40+Q40+X40+AE40+AL40+AS40+AZ40+BG40+BN40+BU40+CB40+CI40 -> 87791 | G40: =F40/E40 -> 0.16151266 | H40: 47459 | I40: 47459 | J40: =威高广场1月实际!I40 -> 47174.5 | O40: =威高广场2月实际!F40 -> 40107 | P40: =威高广场2月实际!G40 -> 40107 | Q40: ='2月时间实际 '!E18 -> 40616.5 | V40: ='3月时间实际'!C18 -> 48990 | CJ40: —— | CK40: =CI40-CH40 -> 0 | CL40: =CI40/CH40 -> #DIV/0! | CM40: =CI40/CG40 -> #DIV/0!
...

Sheet 1月时间实际
A1: 2026年1月时间实际
A2: 注：人员数量如有变化，请及时更改，填写粉色区域
A3: 部门 | B3: 预定 | C3: 预定 | E3: 实际
B4: 人数 | C4: 正常时间 | D4: 加班时间 | E4: 正常时间 | F4: 加班时间
A5: 营销 | B5: 13 | C5: 2392 | D5: 20 | E5: 2392 | F5: 101
A6: 环境（NPC） | B6: 5 | C6: 920 | D6: 0 | E6: 900 | F6: 0
A7: 环境（PC） | B7: 10 | C7: 1840 | D7: 368 | E7: 1712 | F7: 0
A8: 工程 | B8: 54 | C8: 9936 | D8: 50 | E8: 9932 | F8: 6
A9: 财务 | B9: 11 | C9: 2024 | D9: 0 | E9: 1916 | F9: 0
A10: 综合 | B10: 20 | C10: 3680 | D10: 0 | E10: 3717 | F10: 3.5
A11: 开乐影城 | B11: 13 | C11: 2656 | D11: 0 | E11: 2417.5 | F11: 0
A12: 美食广场 | B12: 20 | C12: 3600 | D12: 0 | E12: 3405 | F12: 0
A13: 运营中心 | B13: 28 | C13: 5104 | D13: 0 | E13: 6139 | F13: 0
A14: 招商中心 | B14: 6 | C14: 1104 | D14: 0 | E14: 1104 | F14: 0
A15: 顾客中心 | B15: 16 | C15: 2944 | D15: 0 | E15: 2720 | F15: 0
A16: 安管中心（PC） | B16: 11 | C16: 1978 | D16: 553 | E16: 1808 | F16: 550
A17: 安管中心（NPC） | B17: 51 | C17: 9281 | D17: 3772 | E17: 9012 | F17: 3630
A18: 合计 | B18: =SUM(B5:B17) -> 258 | C18: =SUM(C5:C17) -> 47459 | D18: =SUM(D5:D17) -> 4763 | E18: =SUM(E5:E17) -> 47174.5 | F18: =SUM(F5:F17) -> 4290.5
A19: 时光城项目 | B19: 19 | C19: 3496 | D19: 552 | E19: 3369 | F19: 532
A20: 民俗邨项目 | B20: 16 | C20: 2944 | D20: 644 | E20: 2854 | F20: 496
A21: 总计 | B21: =SUM(B18:B20) -> 293 | C21: =SUM(C18:C20) -> 53899 | D21: =SUM(D18:D20) -> 5959 | E21: =SUM(E18:E20) -> 53397.5 | F21: =SUM(F18:F20) -> 5318.5

Sheet 商管公司2月实际
A1: ____商管公司__2026年 2月度核算表（实际）
A2: 项目 | B2: 序号 | C2: 科目 | D2: 计算公式 | E2: 1月实际 | F2: 年度预算 当月目标 | G2: 销售额 占比 | H2: 月度预定 | I2: 销售额 占比 | J2: 月度实绩 | K2: 销售额 占比 | L2: 预（定）实 （绩）差异额 | M2: （实绩达成） 预定比 | N2: （实绩达成） 年度预算比 | O2: 2月预定/1月实际
A3: 收入 | B3: A1 | C3: 民俗邨项目 | D3: 从软件直接取数或统计明细 | E3: =商管公司1月实际!I3 -> 462886.05 | F3: 443280.99 | H3: 443280.99 | I3: =H3/$H$6 -> 0.020415322 | J3: 445312.86 | K3: =J3/$J$6 -> 0.020325264 | L3: =J3-H3 -> 2031.87 | M3: =J3/H3 -> 1.0045837 | N3: =J3/F3 -> 1.0045837 | O3: =F3/E3 -> 0.95764603
B4: A2 | C4: 时光城项目 | D4: 从软件直接取数或统计明细 | E4: =商管公司1月实际!I4 -> 552400 | F4: 487810 | H4: 487810 | I4: =H4/$H$6 -> 0.022466107 | J4: 522043.76 | K4: =J4/$J$6 -> 0.023827467 | L4: =J4-H4 -> 34233.76 | M4: =J4/H4 -> 1.0701785 | N4: =J4/F4 -> 1.0701785 | O4: =F4/E4 -> 0.88307386
B5: A3 | C5: 威高广场项目 | D5: 从软件直接取数或统计明细 | E5: =商管公司1月实际!I5 -> 21136435 | F5: =威高广场2月实际!F15 -> 20479207 | H5: =威高广场2月实际!G15 -> 20782061 | I5: =H5/$H$6 -> 0.95711857 | J5: =威高广场2月实际!I15 -> 20941970 | K5: =J5/$J$6 -> 0.95584727 | L5: =J5-H5 -> 159909.48 | M5: =J5/H5 -> 1.0076946 | N5: =J5/F5 -> 1.0225967 | O5: =F5/E5 -> 0.96890546
B6: A | C6: 总销售额 | D6: A=A1+A2+A3+A4 | E6: =SUM(E3:E5) -> 22151721 | F6: =SUM(F3:F5) -> 21410298 | H6: =SUM(H3:H5) -> 21713152 | J6: =SUM(J3:J5) -> 21909327 | L6: =J6-H6 -> 196175.11 | M6: =J6/H6 -> 1.0090349 | N6: =J6/F6 -> 1.0233079 | O6: =F6/E6 -> 0.96652979
A7: 费用 | B7: B1 | C7: 民俗邨项目 | D7: 从软件直接取数或统计明细 | E7: =商管公司1月实际!I7 -> 126500 | F7: 153300 | H7: 153300 | I7: =H7/$H$6 -> 0.007060237 | J7: 163000 | K7: =J7/$J$6 -> 0.0074397538 | L7: =J7-H7 -> 9700 | M7: =J7/H7 -> 1.0632746 | N7: =J7/F7 -> 1.0632746 | O7: =F7/E7 -> 1.2118577
B8: B2 | C8: 时光城项目 | D8: 从软件直接取数或统计明细 | E8: =商管公司1月实际!I8 -> 396605 | F8: 388100 | H8: 424830 | I8: =H8/$H$6 -> 0.019565561 | J8: 411756 | K8: =J8/$J$6 -> 0.01879364 | L8: =J8-H8 -> -13074 | M8: =J8/H8 -> 0.96922534 | N8: =J8/F8 -> 1.0609534 | O8: =F8/E8 -> 0.97855549
B9: B3 | C9: 威高广场项目 | D9: 从软件直接取数或统计明细 | E9: =商管公司1月实际!I9 -> 14276057 | F9: =威高广场2月实际!F35 -> 14904789 | H9: =威高广场2月实际!G35 -> 14755691 | I9: =H9/$H$6 -> 0.67957388 | J9: =威高广场2月实际!I35 -> 14224296 | K9: =J9/$J$6 -> 0.64923473 | L9: =J9-H9 -> -531394.84 | M9: =J9/H9 -> 0.96398713 | N9: =J9/F9 -> 0.95434401 | O9: =F9/E9 -> 1.044041
B10: B | C10: 费用合计 | D10: B=B1+B2+B3+.....+Bn | E10: =SUM(E7:E9) -> 14799162 | F10: =SUM(F7:F9) -> 15446189 | H10: =SUM(H7:H9) -> 15333821 | J10: =SUM(J7:J9) -> 14799052 | L10: =J10-H10 -> -534768.84 | M10: =J10/H10 -> 0.96512488 | N10: =J10/F10 -> 0.95810379 | O10: =F10/E10 -> 1.0437205
A11: 附加价值部分 | B11: E | C11: 结算收益（总附加价值） | D11: E=C-D | E11: =E6-E10 -> 7352559 | F11: =F6-F10 -> 5964109.1 | G11: =G6-G10 -> 0 | H11: =H6-H10 -> 6379331.1 | J11: =J6-J10 -> 7110275.1 | O11: =F11/E11 -> 0.81116101
A12: 时间 | B12: F1 | C12: 正常出勤时间 | D12: 从软件直接取数或统计明细 | E12: ='1月时间实际'!E21 -> 53397.5 | F12: 53899 | H12: ='2月时间实际 '!C21 -> 44867 | J12: ='2月时间实际 '!E21 -> 45366.5 | L12: =J12-H12 -> 499.5
B13: F2 | C13: 加班时间 | D13: 从软件直接取数或统计明细 | E13: ='1月时间实际'!F21 -> 5318.5 | F13: 5959 | H13: ='2月时间实际 '!D21 -> 5257 | J13: ='2月时间实际 '!F21 -> 5336 | L13: =J13-H13 -> 79
B14: F | C14: 总时间 | D14: F=F1+F2+F3 | E14: =SUM(E12:E13) -> 58716 | F14: =SUM(F12:F13) -> 59858 | H14: =SUM(H12:H13) -> 50124 | J14: =SUM(J12:J13) -> 50702.5 | L14: =J14-H14 -> 578.5
A15: 单位时间附加值部分 | B15: G | C15: 单位时间附加价值 | D15: G=E/F | E15: =E11/E14 -> 125.22241 | F15: =F11/F14 -> 99.637628 | H15: =H11/H14 -> 127.27099 | J15: =J11/J14 -> 140.2352
A16: 其他（根据自家企业特点自行添加）主要是做好余额管理 | B16: J | C16: 人数 | D16: 从软件直接取数或统计明细 | F16: 293 | H16: 293 | J16: ='2月时间实际 '!B21 -> 295
B17: K | D17: 直接取数 | K17: —— | M17: =J17/H17 -> #DIV/0! | N17: =J17/F17 -> #DIV/0!
B18: L | D18: L=A/J | M18: =J18/H18 -> #DIV/0! | N18: =J18/F18 -> #DIV/0!
B19: M | D19: 盘点表 | M19: =J19/H19 -> #DIV/0! | N19: =J19/F19 -> #DIV/0!
A20: 以下为企业经营者及高管需要掌握的信息(根据企业情况而定）
A21: 核算表栏外部分（经营者及管理层需要掌握） | B21: N | C21: 人工费 | D21: 从软件直接取数或工资表+福利 | E21: 2304821.2 | F21: 1929396.7 | H21: 2928855.8 | J21: 2866764.8
B22: O | C22: 税前利润 | D22: 0=E-N | I22: —— | K22: ——
B23: P | C23: 税前利润率 | D23: P=0/A *100% | I23: —— | K23: ——
B24: Q | C24: 单位时间人工费 | D24: Q=N/F | I24: —— | K24: ——

Sheet 威高广场2月实际
A1: 威高广场整体核算表（2月实际）
A2: 项目 | D2: 计算公式 | E2: 1月份完成情况 | F2: 月度预算 | G2: 月度预定 | H2: 销售额占比 | I2: 月度实际 | J2: 销售额占比 | K2: 预实差异额 | L2: 预实完成比 | M2: 实际完成预算比 | N2: 2月预定/1月完成
A3: 销售最大化 | B3: A馆 | D3: A1 | E3: =威高广场1月实际!I3 -> 9617216.9 | F3: 9150810.1 | G3: 9150810.1 | H3: =F3/$F$6 -> 0.62316884 | I3: 9361815.3 | J3: =I3/$I$15 -> 0.44703603 | K3: =I3-G3 -> 211005.26 | L3: =I3/G3 -> 1.0230586 | M3: =I3/F3 -> 1.0230586 | N3: =G3/E3 -> 0.95150293
B4: B馆 | D4: A2 | E4: =威高广场1月实际!I4 -> 3441935.9 | F4: 2946632.8 | G4: 2946632.8 | H4: =F4/$F$6 -> 0.20066527 | I4: 3523589 | J4: =I4/$I$15 -> 0.16825489 | K4: =I4-G4 -> 576956.21 | L4: =I4/G4 -> 1.1958019 | M4: =I4/F4 -> 1.1958019 | N4: =G4/E4 -> 0.85609752
B5: C馆 | D5: A3 | E5: =威高广场1月实际!I5 -> 2563456.5 | F5: 2586876.1 | G5: 2586876.1 | H5: =F5/$F$6 -> 0.17616589 | I5: 2484040.4 | J5: =I5/$I$15 -> 0.11861541 | K5: =I5-G5 -> -102835.69 | L5: =I5/G5 -> 0.96024715 | M5: =I5/F5 -> 0.96024715 | N5: =G5/E5 -> 1.0091359
B6: 租赁版块小计 | E6: =SUM(E3:E5) -> 15622609 | F6: =SUM(F3:F5) -> 14684319 | G6: =SUM(G3:G5) -> 14684319 | H6: =F6/$F$6 -> 1 | I6: =SUM(I3:I5) -> 15369445 | J6: =I6/$I$15 -> 0.73390633 | K6: =I6-G6 -> 685125.78 | L6: =I6/G6 -> 1.046657 | M6: =I6/F6 -> 1.046657 | N6: =G6/E6 -> 0.93994022
B7: 停车场收入 | D7: A4 | E7: =威高广场1月实际!I7 -> 984634 | F7: 1347000 | G7: 1347000 | H7: =F7/$F$6 -> 0.091730505 | I7: 1101803 | J7: =I7/$I$15 -> 0.052612193 | K7: =I7-G7 -> -245197 | L7: =I7/G7 -> 0.81796808 | M7: =I7/F7 -> 0.81796808 | N7: =G7/E7 -> 1.368021
B8: 其他收入 | D8: A5 | E8: =威高广场1月实际!I8 -> 740873.15 | F8: 233700 | G8: 233700 | H8: =F8/$F$6 -> 0.015914936 | I8: -361009.67 | J8: =I8/$I$15 -> -0.017238572 | K8: =I8-G8 -> -594709.67 | L8: =I8/G8 -> -1.5447568 | M8: =I8/F8 -> -1.5447568 | N8: =G8/E8 -> 0.31543861
B9: 餐饮部 | D9: A6 | E9: =威高广场1月实际!I9 -> 358800 | F9: 473000 | G9: 473000 | H9: =F9/$F$6 -> 0.032211232 | I9: 432600 | J9: =I9/$I$15 -> 0.020657082 | K9: =I9-G9 -> -40400 | L9: =I9/G9 -> 0.91458774 | M9: =I9/F9 -> 0.91458774 | N9: =G9/E9 -> 1.3182832
B10: 写字楼 | D10: A7 | E10: =威高广场1月实际!I10 -> 434300 | F10: 459300 | G10: 459300 | H10: =F10/$F$6 -> 0.031278264 | I10: 433000 | J10: =I10/$I$15 -> 0.020676182 | K10: =I10-G10 -> -26300 | L10: =I10/G10 -> 0.94273895 | M10: =I10/F10 -> 0.94273895 | N10: =G10/E10 -> 1.0575639
B11: 酒店及配套 | D11: A8 | E11: =威高广场1月实际!I11 -> 492433.89 | F11: 492433.89 | G11: 492433.89 | H11: =F11/$F$6 -> 0.033534677 | I11: 492433.57 | J11: =I11/$I$15 -> 0.023514195 | K11: =I11-G11 -> -0.32 | L11: =I11/G11 -> 0.99999935 | M11: =I11/F11 -> 0.99999935 | N11: =G11/E11 -> 1
B12: 能源收入 | D12: A9 | E12: =威高广场1月实际!I12 -> 2206885 | F12: 1916800 | G12: 2219654 | H12: =F12/$F$6 -> 0.1305338 | I12: 2473684 | J12: =I12/$I$15 -> 0.11812088 | K12: =I12-G12 -> 254030 | L12: =I12/G12 -> 1.1144458 | M12: =I12/F12 -> 1.290528 | N12: =G12/E12 -> 1.005786
B13: 推广收入 | D13: A10 | E13: 219600 | F13: 176300 | G13: 176300 | H13: =F13/$F$6 -> 0.012006005 | I13: 221700 | J13: =I13/$I$15 -> 0.010586396 | K13: =I13-G13 -> 45400 | L13: =I13/G13 -> 1.2575156 | M13: =I13/F13 -> 1.2575156 | N13: =G13/E13 -> 0.80282332
B14: 开乐影城 | D14: A11 | E14: =威高广场1月实际!I14 -> 76299.27 | F14: 696354.13 | G14: 696354.13 | H14: =F14/$F$6 -> 0.047421615 | I14: 778314.82 | J14: =I14/$I$15 -> 0.03716531 | K14: =I14-G14 -> 81960.693 | L14: =I14/G14 -> 1.1176997 | M14: =I14/F14 -> 1.1176997 | N14: =G14/E14 -> 9.1266158
A15: 总收入金额 | D15: A=A1+...A6 | E15: =SUM(E6:E14) -> 21136435 | F15: =SUM(F6:F14) -> 20479207 | G15: =SUM(G6:G14) -> 20782061 | I15: =SUM(I6:I14) -> 20941970 | K15: =I15-G15 -> 159909.48 | L15: =I15/G15 -> 1.0076946 | M15: =I15/F15 -> 1.0225967 | N15: =G15/E15 -> 0.98323399
B16: 年度销售额累计 | J16: =I16/$I$15 -> 0 | K16: =I16-G16 -> 0 | L16: =I16/G16 -> #DIV/0! | M16: =I16/F16 -> #DIV/0! | N16: =G16/E16 -> #DIV/0!
A17: 费用最小化 | B17: 财务费用（利息） | D17: F1 | E17: =威高广场1月实际!I17 -> 8982059.5 | F17: 9456669 | G17: 9456669 | H17: =G17/$G$15 -> 0.45504 | I17: 9456669 | J17: =I17/$I$15 -> 0.45156539 | K17: =I17-G17 -> 0 | L17: =I17/G17 -> 1 | M17: =I17/F17 -> 1 | N17: =G17/E17 -> 1.0528397
B18: 商户能源费 | D18: F2 | E18: =威高广场1月实际!I18 -> 1931025 | F18: 1916800 | G18: 2014569 | H18: =G18/$G$15 -> 0.096937883 | I18: 1990574 | J18: =I18/$I$15 -> 0.095051896 | K18: =I18-G18 -> -23995 | L18: =I18/G18 -> 0.98808926 | M18: =I18/F18 -> 1.0384881 | N18: =G18/E18 -> 1.0432641
B19: 公区能源费 | D19: F3 | E19: =威高广场1月实际!I19 -> 1633812 | F19: 1847200 | G19: 1605300 | H19: =G19/$G$15 -> 0.077244504 | I19: 1137393 | J19: =I19/$I$15 -> 0.054311651 | K19: =I19-G19 -> -467907 | L19: =I19/G19 -> 0.70852364 | M19: =I19/F19 -> 0.61573896 | N19: =G19/E19 -> 0.98254879
B20: 推广费 | D20: F4 | E20: =威高广场1月实际!I20 -> 566899.39 | F20: 265182.5 | G20: 335182.5 | H20: =G20/$G$15 -> 0.016128453 | I20: 496596.85 | J20: =I20/$I$15 -> 0.023712995 | K20: =I20-G20 -> 161414.35 | L20: =I20/G20 -> 1.4815715 | M20: =I20/F20 -> 1.8726607 | N20: =G20/E20 -> 0.59125571
B21: 外包费用 | D21: F5 | E21: =威高广场1月实际!I21 -> 517775.66 | F21: 520448.66 | G21: 520448.66 | H21: =G21/$G$15 -> 0.025043169 | I21: 520448.66 | J21: =I21/$I$15 -> 0.024851943 | K21: =I21-G21 -> 0 | L21: =I21/G21 -> 1 | M21: =I21/F21 -> 1 | N21: =G21/E21 -> 1.0051625
B22: 修理费 | D22: F6 | E22: =威高广场1月实际!I22 -> 200122 | F22: 291720 | G22: 221500 | H22: =G22/$G$15 -> 0.010658231 | I22: 123336 | J22: =I22/$I$15 -> 0.0058894171 | K22: =I22-G22 -> -98164 | L22: =I22/G22 -> 0.55682167 | M22: =I22/F22 -> 0.42278898 | N22: =G22/E22 -> 1.1068248
B23: 维保费 | D23: F7 | E23: =威高广场1月实际!I23 -> 210429 | F23: 210429 | G23: 210429 | H23: =G23/$G$15 -> 0.010125512 | I23: 195211.06 | J23: =I23/$I$15 -> 0.009321523 | K23: =I23-G23 -> -15217.94 | L23: =I23/G23 -> 0.92768136 | M23: =I23/F23 -> 0.92768136 | N23: =G23/E23 -> 1
B24: 法律事务费 | D24: F8 | E24: =威高广场1月实际!I24 -> 0 | F24: 101546 | G24: 101546 | H24: =G24/$G$15 -> 0.0048862334 | I24: 101546 | J24: =I24/$I$15 -> 0.0048489229 | K24: =I24-G24 -> 0 | L24: =I24/G24 -> 1 | M24: =I24/F24 -> 1
B25: 招商配套费 | D25: F10 | E25: =威高广场1月实际!I25 -> 18000 | F25: 50509.68 | G25: 50509.68 | H25: =G25/$G$15 -> 0.0024304461 | I25: 0 | J25: =I25/$I$15 -> 0 | K25: =I25-G25 -> -50509.68 | L25: =I25/G25 -> 0 | M25: =I25/F25 -> 0 | N25: =G25/E25 -> 2.8060933
B26: 财务费用（保险） | D26: F11 | E26: =威高广场1月实际!I26 -> 67200 | F26: 67200 | G26: 67200 | H26: =G26/$G$15 -> 0.003233558 | I26: 55900 | J26: =I26/$I$15 -> 0.0026692808 | K26: =I26-G26 -> -11300 | L26: =I26/G26 -> 0.83184524 | M26: =I26/F26 -> 0.83184524 | N26: =G26/E26 -> 1 | O26: 3927.02 | P26: 6848.63 | Q26: 46340.85
B27: 摊销费用（日常摊销） | D27: F12 | E27: =威高广场1月实际!I27 -> 33758.47 | F27: 33200 | G27: 33200 | H27: =G27/$G$15 -> 0.0015975316 | I27: 57116.5 | J27: =I27/$I$15 -> 0.0027273699 | K27: =I27-G27 -> 23916.5 | L27: =I27/G27 -> 1.7203765 | M27: =I27/F27 -> 1.7203765 | N27: =G27/E27 -> 0.98345689
B28: 业务招待费 | D28: F13 | E28: =威高广场1月实际!I28 -> 4523.38 | F28: 27000 | G28: 27000 | H28: =G28/$G$15 -> 0.0012991974 | I28: 4397 | J28: =I28/$I$15 -> 0.00020996114 | K28: =I28-G28 -> -22603 | L28: =I28/G28 -> 0.16285185 | M28: =I28/F28 -> 0.16285185 | N28: =G28/E28 -> 5.9689878
B29: 折旧费（固定资产） | D29: F14 | E29: =威高广场1月实际!I29 -> 30968.67 | F29: 37300 | G29: 37300 | H29: =G29/$G$15 -> 0.0017948172 | I29: 32165.97 | J29: =I29/$I$15 -> 0.0015359572 | K29: =I29-G29 -> -5134.03 | L29: =I29/G29 -> 0.86235845 | M29: =I29/F29 -> 0.86235845 | N29: =G29/E29 -> 1.2044431
B30: 差旅费 | D30: F15 | E30: =威高广场1月实际!I30 -> 4030.47 | F30: 800 | G30: 800 | H30: =G30/$G$15 -> 3.8494738e-05 | I30: 0 | J30: =I30/$I$15 -> 0 | K30: =I30-G30 -> -800 | L30: =I30/G30 -> 0 | M30: =I30/F30 -> 0 | N30: =G30/E30 -> 0.19848802
B31: 办公费用 | D31: F16 | E31: =威高广场1月实际!I31 -> 2425.02 | F31: 14100 | G31: 14100 | H31: =G31/$G$15 -> 0.00067846976 | I31: 1702 | J31: =I31/$I$15 -> 8.1272199e-05 | K31: =I31-G31 -> -12398 | L31: =I31/G31 -> 0.12070922 | M31: =I31/F31 -> 0.12070922 | N31: =G31/E31 -> 5.814385
B32: 网络通讯费 | D32: F17 | E32: =威高广场1月实际!I32 -> 13750.33 | F32: 3400 | G32: 3400 | H32: =G32/$G$15 -> 0.00016360264 | I32: 20064.06 | J32: =I32/$I$15 -> 0.0009580789 | K32: =I32-G32 -> 16664.06 | L32: =I32/G32 -> 5.9011941 | M32: =I32/F32 -> 5.9011941 | N32: =G32/E32 -> 0.24726679
B33: 网络费 | D33: F18 | E33: =威高广场1月实际!I33 -> 8387 | F33: 8387 | G33: 8387 | H33: =G33/$G$15 -> 0.00040356921 | I33: 8387 | J33: =I33/$I$15 -> 0.00040048762 | K33: =I33-G33 -> 0 | L33: =I33/G33 -> 1 | M33: =I33/F33 -> 1 | N33: =G33/E33 -> 1
B34: 对客服务费 | D34: F19 | E34: =威高广场1月实际!I34 -> 50890.9 | F34: 52897 | G34: 48150 | H34: =G34/$G$15 -> 0.0023169021 | I34: 22788.9 | J34: =I34/$I$15 -> 0.0010881927 | K34: =I34-G34 -> -25361.1 | L34: =I34/G34 -> 0.47328972 | M34: =I34/F34 -> 0.43081649 | N34: =G34/E34 -> 0.94614165
A35: 费用合计 | D35: G | E35: =SUM(E17:E34) -> 14276057 | F35: =SUM(F17:F34) -> 14904789 | G35: =SUM(G17:G34) -> 14755691 | I35: =SUM(I17:I34) -> 14224296
A36: 结算收益（附加价值） | D36: I=A-G | E36: =E15-E35 -> 6860377.9 | F36: =F15-F35 -> 5574418.2 | G36: =G15-G35 -> 6026370.2 | I36: =I15-I35 -> 6717674.5
A37: 效率最大化 | B37: 平均总投入人员（个） | C37: 正常人员 | D37: L1 | E37: 263 | F37: ='2月时间实际 '!B18 -> 260 | G37: 260 | I37: 261 | K37: =I37-G37 -> 1 | L37: =I37/G37 -> 1.0038462 | M37: =I37/F37 -> 1.0038462
C38: 新增人员 | D38: L2 | E38: 0 | F38: 0 | G38: 0 | I38: 0 | K38: =I38-G38 -> 0 | L38: =I38/G38 -> #DIV/0! | M38: =I38/F38 -> #DIV/0!
C39: 总人员合计 | D39: L=L1+L2 | E39: =SUM(E37:E38) -> 263 | F39: =SUM(F37:F38) -> 260 | G39: =SUM(G37:G38) -> 260 | I39: =SUM(I37:I38) -> 261 | K39: =I39-G39 -> 1 | L39: =I39/G39 -> 1.0038462 | M39: =I39/F39 -> 1.0038462
B40: 总时间（小时） | C40: 正常时间 | D40: M1 | E40: =威高广场1月实际!I40 -> 47174.5 | F40: ='2月时间实际 '!C18 -> 40107 | G40: ='2月时间实际 '!C18 -> 40107 | I40: ='2月时间实际 '!E18 -> 40616.5 | K40: =I40-G40 -> 509.5 | L40: =I40/G40 -> 1.0127035 | M40: =I40/F40 -> 1.0127035
...

Sheet 2月时间实际 
A1: 2026年2月时间预定
A2: 注：人员数量如有变化，请及时更改，填写粉色区域
A3: 部门 | B3: 预定 | C3: 预定 | E3: 实际
B4: 人数 | C4: 正常时间 | D4: 加班时间 | E4: 正常时间 | F4: 加班时间
A5: 营销 | B5: 14 | C5: 1904 | D5: 130 | E5: 1904 | F5: 125.5
A6: 环境（NPC） | B6: 5 | C6: 680 | D6: 0 | E6: 708 | F6: 0
A7: 环境（PC） | B7: 10 | C7: 1380 | D7: 272 | E7: 1432 | F7: 264
A8: 工程 | B8: 56 | C8: 7616 | D8: 100 | E8: 8268 | F8: 22.5
A9: 财务 | B9: 11 | C9: 1632 | D9: 0 | E9: 1428 | F9: 0
A10: 综合 | B10: 20 | C10: 2856 | D10: 0 | E10: 2912 | F10: 4
A11: 开乐影城 | B11: 13 | C11: 3509 | D11: 0 | E11: 3204.5 | F11: 0
A12: 美食广场 | B12: 20 | C12: 3264 | D12: 0 | E12: 3200 | F12: 0
A13: 运营中心 | B13: 28 | C13: 4032 | D13: 0 | E13: 5064 | F13: 0
A14: 招商中心 | B14: 6 | C14: 816 | D14: 0 | E14: 816 | F14: 0
A15: 顾客中心 | B15: 15 | C15: 2040 | D15: 0 | E15: 2096 | F15: 0
A16: 安管中心（PC） | B16: 11 | C16: 1864 | D16: 557 | E16: 1736 | F16: 548
A17: 安管中心（NPC） | B17: 51 | C17: 8514 | D17: 3314 | E17: 7848 | F17: 3186
A18: 合计 | B18: =SUM(B5:B17) -> 260 | C18: =SUM(C5:C17) -> 40107 | D18: =SUM(D5:D17) -> 4373 | E18: =SUM(E5:E17) -> 40616.5 | F18: =SUM(F5:F17) -> 4150
A19: 时光城项目 | B19: 19 | C19: 2584 | D19: 408 | E19: 2558 | F19: 404
A20: 民俗邨项目 | B20: 16 | C20: 2176 | D20: 476 | E20: 2192 | F20: 782
A21: 总计 | B21: =SUM(B18:B20) -> 295 | C21: =SUM(C18:C20) -> 44867 | D21: =SUM(D18:D20) -> 5257 | E21: =SUM(E18:E20) -> 45366.5 | F21: =SUM(F18:F20) -> 5336

Sheet 商管公司3月实际
A1: ____商管公司__2026年 3月度核算表（实际）
A2: 项目 | B2: 序号 | C2: 科目 | D2: 计算公式 | E2: 2月实际 | F2: 年度预算 当月目标 | G2: 月度预定 | H2: 销售额 占比 | I2: 月度实绩 | J2: 销售额 占比 | K2: 预（定）实 （绩）差异额 | L2: （实绩达成） 预定比 | M2: （实绩达成） 年度预算比 | N2: 2月预定/1月实际
A3: 收入 | B3: A1 | C3: 民俗邨项目 | D3: 从软件直接取数或统计明细 | E3: =商管公司2月实际!J3 -> 445312.86 | F3: 495614.47 | G3: 495614.47 | H3: =G3/$G$6 -> 0.022206449 | N3: =F3/E3 -> 1.1129579
B4: A2 | C4: 时光城项目 | D4: 从软件直接取数或统计明细 | E4: =商管公司2月实际!J4 -> 522043.76 | F4: 447221 | G4: 447221 | H4: =G4/$G$6 -> 0.020038136 | N4: =F4/E4 -> 0.85667339
B5: A3 | C5: 威高广场项目 | D5: 从软件直接取数或统计明细 | E5: =商管公司2月实际!J5 -> 20941970 | F5: =威高广场3月实际!F15 -> 21396500 | G5: =威高广场3月实际!G15 -> 21375657 | H5: =G5/$G$6 -> 0.95775541 | N5: =F5/E5 -> 1.0217043
B6: A | C6: 总销售额 | D6: A=A1+A2+A3+A4 | E6: =SUM(E3:E5) -> 21909327 | F6: =SUM(F3:F5) -> 22339336 | G6: =SUM(G3:G5) -> 22318493 | N6: =F6/E6 -> 1.0196267
A7: 费用 | B7: B1 | C7: 民俗邨项目 | D7: 从软件直接取数或统计明细 | E7: =商管公司2月实际!J7 -> 163000 | F7: 133200 | G7: 133200 | H7: =G7/$G$6 -> 0.0059681449 | N7: =F7/E7 -> 0.81717791
B8: B2 | C8: 时光城项目 | D8: 从软件直接取数或统计明细 | E8: =商管公司2月实际!J8 -> 411756 | F8: 320276 | G8: 320276 | H8: =G8/$G$6 -> 0.014350252 | N8: =F8/E8 -> 0.77782959
B9: B3 | C9: 威高广场项目 | D9: 从软件直接取数或统计明细 | E9: =商管公司2月实际!J9 -> 14224296 | F9: =威高广场3月实际!F35 -> 14783560 | G9: =威高广场3月实际!G35 -> 14761660 | H9: =G9/$G$6 -> 0.66140934 | N9: =F9/E9 -> 1.0393175
B10: B | C10: 费用合计 | D10: B=B1+B2+B3+.....+Bn | E10: =SUM(E7:E9) -> 14799052 | F10: =SUM(F7:F9) -> 15237036 | G10: =SUM(G7:G9) -> 15215136 | N10: =F10/E10 -> 1.0295954
A11: 附加价值部分 | B11: E | C11: 结算收益（总附加价值） | D11: E=C-D | E11: =E6-E10 -> 7110275.1 | F11: =F6-F10 -> 7102300.3 | G11: =G6-G10 -> 7103357.3 | N11: =F11/E11 -> 0.99887841
A12: 时间 | B12: F1 | C12: 正常出勤时间 | D12: 从软件直接取数或统计明细 | E12: ='2月时间实际 '!E21 -> 45366.5 | F12: ='3月时间实际'!C21 -> 56166 | G12: ='3月时间实际'!C21 -> 56166
B13: F2 | C13: 加班时间 | D13: 从软件直接取数或统计明细 | E13: ='2月时间实际 '!F21 -> 5336 | F13: ='3月时间实际'!D21 -> 6230 | G13: ='3月时间实际'!D21 -> 6230
B14: F | C14: 总时间 | D14: F=F1+F2+F3 | E14: =SUM(E12:E13) -> 50702.5 | F14: =SUM(F12:F13) -> 62396 | G14: =SUM(G12:G13) -> 62396
A15: 单位时间附加值部分 | B15: G | C15: 单位时间附加价值 | D15: G=E/F | E15: =E11/E14 -> 140.2352 | F15: =F11/F14 -> 113.82621 | G15: =G11/G14 -> 113.84315
A16: 其他（根据自家企业特点自行添加）主要是做好余额管理 | B16: J | C16: 人数 | D16: 从软件直接取数或统计明细 | E16: ='3月时间实际'!B21 -> 294 | F16: ='3月时间实际'!B21 -> 294 | G16: ='3月时间实际'!B21 -> 294
A17: 以下为企业经营者及高管需要掌握的信息(根据企业情况而定）
A18: 核算表栏外部分（经营者及管理层需要掌握） | B18: N | C18: 人工费 | D18: 从软件直接取数或工资表+福利 | E18: 2179054
B19: O | C19: 税前利润 | D19: 0=E-N | H19: —— | J19: ——
B20: P | C20: 税前利润率 | D20: P=0/A *100% | H20: —— | J20: ——
B21: Q | C21: 单位时间人工费 | D21: Q=N/F | H21: —— | J21: ——

Sheet 威高广场3月实际
A1: 威高广场整体核算表（3月实际）
A2: 项目 | D2: 计算公式 | E2: 2月份完成情况 | F2: 月度预算 | G2: 月度预定 | H2: 销售额占比 | I2: 月度实际 | J2: 销售额占比 | K2: 预实差异额 | L2: 预实完成比 | M2: 实际完成预算比 | N2: 3月预定/2月完成
A3: 销售最大化 | B3: A馆 | D3: A1 | E3: =威高广场2月实际!I3 -> 9361815.3 | F3: 10060063 | G3: 10060063 | H3: =F3/$F$6 -> 0.59868184 | N3: =G3/E3 -> 1.0745847
B4: B馆 | D4: A2 | E4: =威高广场2月实际!I4 -> 3523589 | F4: 4466249.9 | G4: 4466249.9 | H4: =F4/$F$6 -> 0.26578984 | N4: =G4/E4 -> 1.2675286
B5: C馆 | D5: A3 | E5: 2484040.4 | F5: 2277375.8 | G5: 2277375.8 | H5: =F5/$F$6 -> 0.13552832 | N5: =G5/E5 -> 0.91680304
B6: 租赁版块小计 | E6: =威高广场2月实际!I6 -> 15369445 | F6: =SUM(F3:F5) -> 16803689 | G6: =SUM(G3:G5) -> 16803689 | H6: =F6/$F$6 -> 1 | N6: =G6/E6 -> 1.0933179
B7: 停车场收入 | D7: A4 | E7: =威高广场2月实际!I7 -> 1101803 | F7: 1015400 | G7: 1015400 | H7: =F7/$F$6 -> 0.060427207 | N7: =G7/E7 -> 0.92158036
B8: 其他收入 | D8: A5 | E8: =威高广场2月实际!I8 -> -361009.67 | F8: 100400 | G8: 100400 | H8: =F8/$F$6 -> 0.0059748785 | N8: =G8/E8 -> -0.27810889
B9: 餐饮部 | D9: A6 | E9: =威高广场2月实际!I9 -> 432600 | F9: 294000 | G9: 294000 | H9: =F9/$F$6 -> 0.017496158 | N9: =G9/E9 -> 0.67961165
B10: 写字楼 | D10: A7 | E10: =威高广场2月实际!I10 -> 433000 | F10: 459300 | G10: 459300 | H10: =F10/$F$6 -> 0.027333284 | N10: =G10/E10 -> 1.060739
B11: 酒店及配套 | D11: A8 | E11: =威高广场2月实际!I11 -> 492433.57 | F11: 492433.89 | G11: 492433.89 | H11: =F11/$F$6 -> 0.029305106 | N11: =G11/E11 -> 1.0000006
B12: 能源收入 | D12: A9 | E12: =威高广场2月实际!I12 -> 2473684 | F12: 1986541 | G12: 1965698 | H12: =F12/$F$6 -> 0.11822053 | N12: =G12/E12 -> 0.79464394
B13: 推广收入 | D13: A10 | E13: =威高广场2月实际!I13 -> 221700 | F13: 163300 | G13: 163300 | H13: =F13/$F$6 -> 0.0097181041 | N13: =G13/E13 -> 0.73658097
B14: 开乐影城 | D14: A11 | E14: =威高广场2月实际!I14 -> 778314.82 | F14: 81436.438 | G14: 81436.438 | H14: =F14/$F$6 -> 0.0048463428 | N14: =G14/E14 -> 0.10463175
A15: 总收入金额 | D15: A=A1+...A6 | E15: =SUM(E6:E14) -> 20941970 | F15: =SUM(F6:F14) -> 21396500 | G15: =SUM(G6:G14) -> 21375657 | N15: =G15/E15 -> 1.020709
B16: 年度销售额累计 | N16: =G16/E16 -> #DIV/0!
A17: 费用最小化 | B17: 财务费用（利息） | D17: F1 | E17: =威高广场2月实际!I17 -> 9456669 | F17: 9707200 | G17: 9707200 | H17: =G17/$G$15 -> 0.45412405 | N17: =G17/E17 -> 1.0264925
B18: 商户能源费 | D18: F2 | E18: =威高广场2月实际!I18 -> 1990574 | F18: 1695700 | G18: 1695700 | H18: =G18/$G$15 -> 0.079328554 | N18: =G18/E18 -> 0.85186484
B19: 公区能源费 | D19: F3 | E19: =威高广场2月实际!I19 -> 1137393 | F19: 1343400 | G19: 1343400 | H19: =G19/$G$15 -> 0.06284719 | N19: =G19/E19 -> 1.1811221
B20: 推广费 | D20: F4 | E20: =威高广场2月实际!I20 -> 496596.85 | F20: 659782.5 | G20: 659782.5 | H20: =G20/$G$15 -> 0.030866068 | N20: =G20/E20 -> 1.3286079
